Workbook

Sheet Cover
B2: BILL OF QUANTITIES
B4: ELECTRICAL POWER DISTRIBUTION WORKS — DEWA AUTHORITY
B7: Project | C7: Proposed B+G+8+R Commercial & Residential Building
B8: Owner / Client | C8: Qutaiba Ameen Abdal Kija
B9: Plot No. | C9: 6731315 — Al Barsha South Third, Dubai, UAE
B10: MEP Consultant | C10: Future Art Engineering Consultancy
B11: Authority | C11: DEWA (Dubai Electricity & Water Authority)
B13: TENDER DETAILS
B14: Job No. | C14: FA_P379 / CRs B/010/25
B15: Drawing Ref | C15: P-001 … P-300 (14 sheets, Power)
B16: Drawing Date | C16: 19/06/2026
B17: BOQ Date | C17: 19/06/2026
B18: Addendum No. | C18: 0
B19: BOQ Status | C19: PRICED (INDICATIVE) — Dubai 2026 rates · POWER scope · review before submission
B20: Currency | C20: AED (UAE Dirham)
B21: VAT Rate | C21: 5% (UAE Federal)
B23: CONTRACTOR DETAILS
B24: Contractor | C24: SABI Engineering & Contracting LLC
B25: Address | C25: Dubai, United Arab Emirates
B26: Phone | C26: +971 4 XXX XXXX
B27: Email | C27: estimation@sabi.ae
B28: TRN | C28: 100XXXXXXXXXXXXX
B30: LIST OF BILLS
B31: Bill | C31: Description | H31: Sheet
B32: 1 | C32: General Items / Preliminaries | H32: Bill 1
B33: 2 | C33: HV / LV Main Distribution (Transformer, MDB, Generator, ATS, Capacitors) | H33: Bill 2
B34: 3 | C34: Sub-Main Distribution Boards (SMDBs) | H34: Bill 3
B35: 4 | C35: Distribution Boards (DBs) & Consumer Units | H35: Bill 4
B36: 5 | C36: LV Power Cables (Main + Distribution + Final Circuits) | H36: Bill 5
B37: 6 | C37: Cable Containment (Tray, Ladder, Trunking, Conduit) | H37: Bill 6
B38: 7 | C38: Wiring Devices & Accessories | H38: Bill 7
B39: 8 | C39: Lighting Fixtures (Internal + External) | H39: Bill 8
B40: 9 | C40: Earthing & Lightning Protection | H40: Bill 9
B41: 10 | C41: Emergency Lighting & Life Safety | H41: Bill 10
B42: 11 | C42: ELV Containment (Telephone, Data, CCTV, ACS, MATV, FA) | H42: Bill 11
B43: 12 | C43: Metering & Monitoring | H43: Bill 12
B44: 13 | C44: Testing, Commissioning & DEWA Approval | H44: Bill 13
B46: COMPLIANCE SUMMARY — what this BOQ already covers
B47: ✓ DEWA Distribution Standards · Dubai Municipality (DM) · Dubai Civil Defence (DCD) — see Preamble Sheet § 0 Statutory Compliance
B48: ✓ DEWA Smart Metering programme — Bill 12 (smart kWh meters single + three-phase, AMI-ready, MDM integration, Shams Dubai bi-directional, IEC 62052/62053)
...

Sheet Preamble & Standards
B2: PREAMBLE & APPLICABLE STANDARDS
B4: 0. STATUTORY COMPLIANCE — UAE / DUBAI AUTHORITIES
B5: The works under this BOQ shall fully comply with the requirements of the following Dubai and UAE authorities. The contractor shall obtain all approvals, attend witnessed inspections, and submit all documentation required by each authority as part of the contract.
B6: Authority | C6: Scope of compliance
B7: DEWA | C7: Dubai Electricity & Water Authority — Distribution Standards, Service Connection Specifications, Smart Grid / Smart Metering programme, witnessed inspections, energising, meter sealing, As-Built filing.
B8: Dubai Municipality | C8: Building Code, Local Order 89/1994 (Building Regulations) and amendments, electrical safety inspections, occupancy / completion certificate clearance.
B9: DCD | C9: Dubai Civil Defence — UAE Fire & Life Safety Code of Practice (latest edition); fire-rated containment, FR/LSZH cable selection, emergency lighting, fire-fighter's lift, smoke-control fan power supplies.
B10: UAE Federal | C10: Federal Tax Authority — VAT (5%) per UAE VAT Law (Federal Decree-Law No. 8 of 2017); MoCCAE / ESMA conformity certificates for electrical equipment placed on UAE market.
B12: 1. SCOPE OF WORKS
B13: Supply, installation, testing and commissioning of the complete LV electrical distribution system, lighting, small power, earthing & lightning protection, metering and life-safety related electrical installations for the project, in accordance with the tender drawings, specifications, applicable standards, and authority requirements (DEWA, Dubai Municipality, Dubai Civil Defence). The scope shall include all materials, labour, plant, supervision, transport, scaffolding, builder's work in connection, testing instruments, commissioning, As-Built drawings and O&M manuals.
B15: 2. APPLICABLE STANDARDS
B16: Standard | C16: Description
B17: DEWA | C17: Distribution Standards & Authority Regulations (latest edition)
B18: DEWA Smart Grid | C18: Smart Metering Programme / AMI Specifications / Shams Dubai
B19: DM | C19: Dubai Municipality Building Code & Electrical Inspection Standards
B20: DM Local Order | C20: Local Order 89/1994 — Building Regulations and amendments
B21: DCD | C21: Dubai Civil Defence — UAE Fire & Life Safety Code of Practice (latest)
B22: BS 7671 | C22: IEE Wiring Regulations (18th Edition / latest)
B23: IEC 60364 | C23: Low-voltage electrical installations
B24: IEC 60439 | C24: LV switchgear and controlgear assemblies (Form separation)
B25: IEC 60947 | C25: LV switchgear (ACBs, MCCBs, contactors)
B26: IEC 60331 | C26: Fire-resisting characteristics of electric cables
B27: BS 6387 CWZ | C27: Performance requirements for fire-rated cables
... B35: UAE FTA | C35: Federal Tax Authority — VAT (5%) on tender total per Federal Decree-Law 8/2017
B37: 3. ABBREVIATIONS
B38: Abbr. | C38: Meaning
B39: ACB | C39: Air Circuit Breaker
B40: MCCB | C40: Moulded Case Circuit Breaker
B41: MCB | C41: Miniature Circuit Breaker
B42: RCD | C42: Residual Current Device
B43: LVP | C43: LV Panel (Main)
B44: SMDB | C44: Sub-Main Distribution Board
B45: ESMDB | C45: Emergency SMDB
B46: DB | C46: Distribution Board
B47: EDB | C47: Emergency DB
B48: ATS | C48: Automatic Transfer Switch
B49: XLPE | C49: Cross-Linked Polyethylene
... B64: IP55/IP65 | C64: Ingress Protection ratings
B67: 4. PRICING NOTES
B68: (1) | C68: All rates shall include supply, delivery, off-loading, storage, installation, fixings, support steelwork, painting, identification labelling, testing, commissioning, and handover.
...

Sheet Bill 1 - Preliminaries
A1: BILL No. 1 — GENERAL ITEMS / PRELIMINARIES
A2: Project: Proposed B+G+8+R Commercial & Residential Building, Plot 6731315, Al Barsha South Third, Dubai, UAE | Job: FA_P379 / CRs B/010/25 | Authority: DEWA (Dubai Electricity & Water Authority)
A3: Item | B3: Description | C3: Reference | D3: Unit | E3: Qty | F3: Rate (AED) | G3: Amount (AED) | H3: Origin / Brand
A4: 1.1 — PROJECT MOBILISATION & SITE ESTABLISHMENT
A5: 1.1.1 | B5: Mobilisation to site, including transport of plant, tools, materials and personnel. | C5: — | D5: Sum | E5: 1 | F5: 125000 | G5: =IF(OR(E5="",F5=""),"",E5*F5) | H5: 📋 — (contractor selection)
A6: 1.1.2 | B6: Site offices, storage compounds, sanitary and welfare facilities for the duration of the works. | C6: — | D6: Sum | E6: 1 | F6: 85000 | G6: =IF(OR(E6="",F6=""),"",E6*F6) | H6: 📋 — (contractor selection)
A7: 1.1.3 | B7: Site hoarding, fencing and security as per main contractor / consultant requirements. | C7: — | D7: Sum | E7: 1 | F7: 35000 | G7: =IF(OR(E7="",F7=""),"",E7*F7) | H7: 📋 — (contractor selection)
A8: 1.1.4 | B8: Health & Safety plan, PPE, fall-arrest and electrical safety (LOTO) provisions for the duration. | C8: — | D8: Sum | E8: 1 | F8: 18000 | G8: =IF(OR(E8="",F8=""),"",E8*F8) | H8: 📋 — (contractor selection)
A9: 1.1.5 | B9: Coordination with main contractor and other MEP trades — shop-drawing review meetings, BIM coordination as required. | C9: — | D9: Sum | E9: 1 | F9: 25000 | G9: =IF(OR(E9="",F9=""),"",E9*F9) | H9: 📋 — (contractor selection)
A10: Sub-Total 1.1 | G10: =SUM(G5:G10)
A12: 1.2 — INSURANCE & BONDS
A13: 1.2.1 | B13: Contractor's All Risks (CAR) insurance for the contract value, full duration plus DLP. | C13: — | D13: Sum | E13: 1 | F13: 85000 | G13: =IF(OR(E13="",F13=""),"",E13*F13) | H13: 📋 — (contractor selection)
A14: 1.2.2 | B14: Workmen's Compensation and Public Liability insurance. | C14: — | D14: Sum | E14: 1 | F14: 45000 | G14: =IF(OR(E14="",F14=""),"",E14*F14) | H14: 📋 — (contractor selection)
A15: 1.2.3 | B15: Performance bond (10% of contract value) — bank guarantee in favour of the employer. | C15: — | D15: Sum | E15: 1 | F15: 18000 | G15: =IF(OR(E15="",F15=""),"",E15*F15) | H15: 📋 — (contractor selection)
A16: 1.2.4 | B16: Advance payment guarantee — bank guarantee against advance. | C16: — | D16: Sum | E16: 1 | F16: 12000 | G16: =IF(OR(E16="",F16=""),"",E16*F16) | H16: 📋 — (contractor selection)
A17: Sub-Total 1.2 | G17: =SUM(G13:G17)
A19: 1.3 — TEMPORARY UTILITIES & TESTING INSTRUMENTS
A20: 1.3.1 | B20: Temporary power supply during construction — generator, distribution, metering, fuel. | C20: — | D20: Sum | E20: 1 | F20: 85000 | G20: =IF(OR(E20="",F20=""),"",E20*F20) | H20: 📋 — (contractor selection)
A21: 1.3.2 | B21: Temporary lighting in areas of work as required for safe execution. | C21: — | D21: Sum | E21: 1 | F21: 25000 | G21: =IF(OR(E21="",F21=""),"",E21*F21) | H21: 📋 — (contractor selection)
A22: 1.3.3 | B22: Provision of all testing instruments — Megger 500V/1000V, earth tester, multimeter, RCD tester, loop tester, calibration certificates current. | C22: — | D22: Sum | E22: 1 | F22: 5500 | G22: =IF(OR(E22="",F22=""),"",E22*F22) | H22: 📋 — (contractor selection)
A23: Sub-Total 1.3 | G23: =SUM(G20:G23)
A25: 1.4 — SUBMITTALS, AS-BUILTS, O&M MANUALS
A26: 1.4.1 | B26: Shop drawings (AutoCAD) — full set, multiple revisions until approved. | C26: — | D26: Sum | E26: 1 | F26: 85000 | G26: =IF(OR(E26="",F26=""),"",E26*F26) | H26: 📋 — (contractor selection)
A27: 1.4.2 | B27: Material approval submittals — datasheets, samples, manufacturer's certificates, country-of-origin declarations. | C27: — | D27: Sum | E27: 1 | F27: 35000 | G27: =IF(OR(E27="",F27=""),"",E27*F27) | H27: 📋 — (contractor selection)
A28: 1.4.3 | B28: As-Built drawings (AutoCAD + PDF, 4 hard copies) at handover. | C28: — | D28: Sum | E28: 1 | F28: 45000 | G28: =IF(OR(E28="",F28=""),"",E28*F28) | H28: 📋 — (contractor selection)
A29: 1.4.4 | B29: Operation & Maintenance manuals (4 hard copies + PDF) at handover, including spare-parts list. | C29: — | D29: Sum | E29: 1 | F29: 38000 | G29: =IF(OR(E29="",F29=""),"",E29*F29) | H29: 📋 — (contractor selection)
A30: 1.4.5 | B30: Defects Liability Period support (12 months from handover) — site attendance, replacement of defective materials, retesting. | C30: — | D30: Sum | E30: 1 | F30: 12000 | G30: =IF(OR(E30="",F30=""),"",E30*F30) | H30: 📋 — (contractor selection)
A31: Sub-Total 1.4 | G31: =SUM(G26:G31)
A33: 1.5 — AUTHORITY FEES, NOCs & PERMITS
A34: 1.5.1 | B34: DEWA HV/LV connection capacity charges (per kVA, DEWA tariff). Provisional sum — final amount per DEWA load-letter response. | C34: DEWA / DM / DCD / RTA tariff | D34: Sum | E34: 1 | F34: 350000 | G34: =IF(OR(E34="",F34=""),"",E34*F34) | H34: 📋 DEWA / DM / DCD / RTA
A35: 1.5.2 | B35: DEWA load-letter application & approval fees (capacity allocation, RMU/substation siting, voltage level confirmation). | C35: DEWA / DM / DCD / RTA tariff | D35: Sum | E35: 1 | F35: 8000 | G35: =IF(OR(E35="",F35=""),"",E35*F35) | H35: 📋 DEWA / DM / DCD / RTA
A36: 1.5.3 | B36: DEWA energising application fee — submission, processing, witness arrangement, meter sealing. | C36: DEWA / DM / DCD / RTA tariff | D36: Sum | E36: 1 | F36: 12000 | G36: =IF(OR(E36="",F36=""),"",E36*F36) | H36: 📋 DEWA / DM / DCD / RTA
A37: 1.5.4 | B37: RTA road-cutting permit + reinstatement (where HV/LV cabling crosses public road or pavement). Provisional sum. | C37: DEWA / DM / DCD / RTA tariff | D37: Sum | E37: 1 | F37: 45000 | G37: =IF(OR(E37="",F37=""),"",E37*F37) | H37: 📋 DEWA / DM / DCD / RTA
A38: 1.5.5 | B38: Dubai Municipality (DM) electrical inspection & completion-certificate fee — for occupancy / completion sign-off. | C38: DEWA / DM / DCD / RTA tariff | D38: Sum | E38: 1 | F38: 18000 | G38: =IF(OR(E38="",F38=""),"",E38*F38) | H38: 📋 DEWA / DM / DCD / RTA
A39: 1.5.6 | B39: Dubai Civil Defence (DCD) electrical clearance NOC fee — life-safety clearance for fire pump, smoke control, emergency lighting. | C39: DEWA / DM / DCD / RTA tariff | D39: Sum | E39: 1 | F39: 12000 | G39: =IF(OR(E39="",F39=""),"",E39*F39) | H39: 📋 DEWA / DM / DCD / RTA
A40: Sub-Total 1.5 | G40: =SUM(G34:G40)
A43: BILL 1 — TOTAL CARRIED TO SUMMARY | G43: =SUMIF(G4:G41,"<>")

Sheet Bill 2 - HV-LV Main
A1: BILL No. 2 — HV / LV MAIN DISTRIBUTION
A2: Project: Proposed B+G+8+R Commercial & Residential Building, Plot 6731315, Al Barsha South Third, Dubai, UAE | Job: FA_P379 / CRs B/010/25 | Authority: DEWA (Dubai Electricity & Water Authority)
A3: Item | B3: Description | C3: Reference | D3: Unit | E3: Qty | F3: Rate (AED) | G3: Amount (AED) | H3: Origin / Brand
A4: 2.1 — HV INCOMING SUPPLY & TRANSFORMER (DEWA-coordinated)
A5: 2.1.1 | B5: DEWA HV incoming service connection (RMU / package substation, supplied & installed by DEWA). Contractor allowance for coordination, application, attendance and acceptance. | C5: P-200 (SLD) / P-300 (LV room) | D5: Lot | E5: 1 | F5: 0 | G5: =IF(OR(E5="",F5=""),"",E5*F5) | H5: 📋 DEWA-listed
A6: 2.1.2 | B6: HV / LV distribution transformer — 2000 kVA, 11 kV / 0.4 kV, 50 Hz, vector group Dyn11, K-Factor rating ≥ K-13 (suitable for non-linear loads — LED lighting, EV chargers, VFDs; uplift to K-20 if EV load > 20 % of MD), cast-resin (dry-type) construction with encapsulated F-class windings, IP31 enclosure, anti-vibration mounts, ±2.5 % / ±5 % off-circuit tap changer, oil-free, low-loss DEWA-listed manufacturer. Sized for Building MD ~? kW + 25 % spare. Includes installation, energising, witnessed routine test, commissioning report. | C6: P-200 (SLD) / P-300 (LV room) | D6: Nr | E6: 1 | F6: 240000 | G6: =IF(OR(E6="",F6=""),"",E6*F6) | H6: 📋 Schneider / ABB / Siemens / Trafo Union
A7: 2.1.3 | B7: 11 kV HV cable (single-core 3×1C, XLPE/CWS/PVC, copper screen) from RMU to transformer HV side — complete with stress cones, heat-shrink terminations, fire stopping at penetrations, earthing, ID phase markers. | C7: P-200 (SLD) / P-300 (LV room) | D7: m | E7: 30 | F7: 18000 | G7: =IF(OR(E7="",F7=""),"",E7*F7) | H7: 📋 — (contractor selection)
A8: 2.1.4 | B8: Transformer room civil / MEP coordination — pressure-relief vents, mechanical ventilation, drainage, fire-rated enclosure (≥ 2 h), DEWA-spec oil bund where oil-filled (N/A for cast-resin) — coordination only. | C8: P-200 (SLD) / P-300 (LV room) | D8: Sum | E8: 1 | F8: 35000 | G8: =IF(OR(E8="",F8=""),"",E8*F8) | H8: 📋 Schneider / ABB / Siemens / Trafo Union
A9: Sub-Total 2.1 | G9: =SUM(G5:G9)
A11: 2.2 — LV PANELS (Supply, Install, Test & Commission)
A12: 2.2.1 | B12: Main LV Panel — sized per Maximum Demand. Supply, install, test, commission complete with ACB, busbars, MCCBs as per SLD. | C12: P-200 (SLD) / P-300 (LV room) | D12: Nr | E12: 1 | G12: =IF(OR(E12="",F12=""),"",E12*F12) | H12: 📐 Coordinate with consultant
A13: Sub-Total 2.2 | G13: =SUM(G12:G13)
A15: 2.3 — STANDBY GENERATOR & ATS
A16: 2.3.1 | B16: Standby generator + ATS — sized per essential-load schedule. Supply, install, commission complete. | C16: P-200 (SLD) / P-300 (LV room) | D16: Set | E16: 1 | F16: 80000 | G16: =IF(OR(E16="",F16=""),"",E16*F16) | H16: 📐 Cummins / Caterpillar / FG Wilson / Perkins
A17: Sub-Total 2.3 | G17: =SUM(G16:G17)
A20: BILL 2 — TOTAL CARRIED TO SUMMARY | G20: =SUMIF(G4:G18,"<>")

Sheet Bill 3 - SMDBs
A1: BILL No. 3 — SUB-MAIN DISTRIBUTION BOARDS (SMDBS)
A2: Project: Proposed B+G+8+R Commercial & Residential Building, Plot 6731315, Al Barsha South Third, Dubai, UAE | Job: FA_P379 / CRs B/010/25 | Authority: DEWA (Dubai Electricity & Water Authority)
A3: Item | B3: Description | C3: Reference | D3: Unit | E3: Qty | F3: Rate (AED) | G3: Amount (AED) | H3: Origin / Brand
A4: 3.1 — TYPICAL FLOOR SMDBs (1F–8F)
A5: 3.1.1 | B5: SMDB-1F: floor-standing SMDB, IP31 powder-coated mild-steel enclosure with padlockable hinged door, 415 V / 3P+N+E, 300A TP MCCB ≥35 kA Icu incomer, busbar 300 A Cu electro-tin plated, Form 2b separation, neutral / earth bars, outgoing MCCBs / MCBs / RCBOs as per SLD, MEB sub-bar bonded to building MEB, ID-engraved circuit labels, padlockable hinged door, manufacturer's factory acceptance test (FAT) certificate. Fire-rated cable glands + LSZH gland-kits at all FR feeder terminations. Connected load 150.86 kW. Supply, install, terminate, energise, witnessed routine test. | C5: P-201 (SLD) / P-103 (1F) | D5: Nr | E5: 1 | F5: 32000 | G5: =IF(OR(E5="",F5=""),"",E5*F5) | H5: 📐 Schneider / Hager / Legrand / ABB
A6: 3.1.2 | B6: SMDB-2F: floor-standing SMDB, IP31 powder-coated mild-steel enclosure with padlockable hinged door, 415 V / 3P+N+E, 300A TP MCCB ≥35 kA Icu incomer, busbar 300 A Cu electro-tin plated, Form 2b separation, neutral / earth bars, outgoing MCCBs / MCBs / RCBOs as per SLD, MEB sub-bar bonded to building MEB, ID-engraved circuit labels, padlockable hinged door, manufacturer's factory acceptance test (FAT) certificate. Fire-rated cable glands + LSZH gland-kits at all FR feeder terminations. Connected load 150.86 kW. Supply, install, terminate, energise, witnessed routine test. | C6: P-201 (SLD) / P-104 (2F) | D6: Nr | E6: 1 | F6: 32000 | G6: =IF(OR(E6="",F6=""),"",E6*F6) | H6: 📐 Schneider / Hager / Legrand / ABB
A7: 3.1.3 | B7: SMDB-3F: floor-standing SMDB, IP31 powder-coated mild-steel enclosure with padlockable hinged door, 415 V / 3P+N+E, 300A TP MCCB ≥35 kA Icu incomer, busbar 300 A Cu electro-tin plated, Form 2b separation, neutral / earth bars, outgoing MCCBs / MCBs / RCBOs as per SLD, MEB sub-bar bonded to building MEB, ID-engraved circuit labels, padlockable hinged door, manufacturer's factory acceptance test (FAT) certificate. Fire-rated cable glands + LSZH gland-kits at all FR feeder terminations. Connected load 150.86 kW. Supply, install, terminate, energise, witnessed routine test. | C7: P-201 (SLD) / P-105 (3F) | D7: Nr | E7: 1 | F7: 32000 | G7: =IF(OR(E7="",F7=""),"",E7*F7) | H7: 📐 Schneider / Hager / Legrand / ABB
A8: 3.1.4 | B8: SMDB-4F: floor-standing SMDB, IP31 powder-coated mild-steel enclosure with padlockable hinged door, 415 V / 3P+N+E, 300A TP MCCB ≥35 kA Icu incomer, busbar 300 A Cu electro-tin plated, Form 2b separation, neutral / earth bars, outgoing MCCBs / MCBs / RCBOs as per SLD, MEB sub-bar bonded to building MEB, ID-engraved circuit labels, padlockable hinged door, manufacturer's factory acceptance test (FAT) certificate. Fire-rated cable glands + LSZH gland-kits at all FR feeder terminations. Connected load 150.86 kW. Supply, install, terminate, energise, witnessed routine test. | C8: P-201 (SLD) / P-104 (4F) | D8: Nr | E8: 1 | F8: 32000 | G8: =IF(OR(E8="",F8=""),"",E8*F8) | H8: 📐 Schneider / Hager / Legrand / ABB
A9: 3.1.5 | B9: SMDB-5F: floor-standing SMDB, IP31 powder-coated mild-steel enclosure with padlockable hinged door, 415 V / 3P+N+E, 300A TP MCCB ≥35 kA Icu incomer, busbar 300 A Cu electro-tin plated, Form 2b separation, neutral / earth bars, outgoing MCCBs / MCBs / RCBOs as per SLD, MEB sub-bar bonded to building MEB, ID-engraved circuit labels, padlockable hinged door, manufacturer's factory acceptance test (FAT) certificate. Fire-rated cable glands + LSZH gland-kits at all FR feeder terminations. Connected load 150.86 kW. Supply, install, terminate, energise, witnessed routine test. | C9: P-201 (SLD) / P-105 (5F) | D9: Nr | E9: 1 | F9: 32000 | G9: =IF(OR(E9="",F9=""),"",E9*F9) | H9: 📐 Schneider / Hager / Legrand / ABB
A10: 3.1.6 | B10: SMDB-6F: floor-standing SMDB, IP31 powder-coated mild-steel enclosure with padlockable hinged door, 415 V / 3P+N+E, 300A TP MCCB ≥35 kA Icu incomer, busbar 300 A Cu electro-tin plated, Form 2b separation, neutral / earth bars, outgoing MCCBs / MCBs / RCBOs as per SLD, MEB sub-bar bonded to building MEB, ID-engraved circuit labels, padlockable hinged door, manufacturer's factory acceptance test (FAT) certificate. Fire-rated cable glands + LSZH gland-kits at all FR feeder terminations. Connected load 150.86 kW. Supply, install, terminate, energise, witnessed routine test. | C10: P-201 (SLD) / P-104 (6F) | D10: Nr | E10: 1 | F10: 32000 | G10: =IF(OR(E10="",F10=""),"",E10*F10) | H10: 📐 Schneider / Hager / Legrand / ABB
A11: 3.1.7 | B11: SMDB-7F: floor-standing SMDB, IP31 powder-coated mild-steel enclosure with padlockable hinged door, 415 V / 3P+N+E, 300A TP MCCB ≥35 kA Icu incomer, busbar 300 A Cu electro-tin plated, Form 2b separation, neutral / earth bars, outgoing MCCBs / MCBs / RCBOs as per SLD, MEB sub-bar bonded to building MEB, ID-engraved circuit labels, padlockable hinged door, manufacturer's factory acceptance test (FAT) certificate. Fire-rated cable glands + LSZH gland-kits at all FR feeder terminations. Connected load 150.86 kW. Supply, install, terminate, energise, witnessed routine test. | C11: P-201 (SLD) / P-105 (7F) | D11: Nr | E11: 1 | F11: 32000 | G11: =IF(OR(E11="",F11=""),"",E11*F11) | H11: 📐 Schneider / Hager / Legrand / ABB
A12: 3.1.8 | B12: SMDB-8F: floor-standing SMDB, IP31 powder-coated mild-steel enclosure with padlockable hinged door, 415 V / 3P+N+E, 300A TP MCCB ≥35 kA Icu incomer, busbar 300 A Cu electro-tin plated, Form 2b separation, neutral / earth bars, outgoing MCCBs / MCBs / RCBOs as per SLD, MEB sub-bar bonded to building MEB, ID-engraved circuit labels, padlockable hinged door, manufacturer's factory acceptance test (FAT) certificate. Fire-rated cable glands + LSZH gland-kits at all FR feeder terminations. Connected load 150.86 kW. Supply, install, terminate, energise, witnessed routine test. | C12: P-201 (SLD) / P-104 (8F) | D12: Nr | E12: 1 | F12: 32000 | G12: =IF(OR(E12="",F12=""),"",E12*F12) | H12: 📐 Schneider / Hager / Legrand / ABB
A13: Sub-Total 3.1 | G13: =SUM(G5:G13)
A15: 3.2 — GROUND FLOOR SMDBs
A16: 3.2.1 | B16: SMDB-G: wall-mounted SMDB, IP31 powder-coated mild-steel enclosure with padlockable hinged door, 415 V / 3P+N+E, 125A TP MCCB ≥35 kA Icu incomer, busbar 125 A Cu electro-tin plated, Form 2b separation, neutral / earth bars, outgoing MCCBs / MCBs / RCBOs as per SLD, MEB sub-bar bonded to building MEB, ID-engraved circuit labels, padlockable hinged door, manufacturer's factory acceptance test (FAT) certificate. Fire-rated cable glands + LSZH gland-kits at all FR feeder terminations. Connected load 60.55 kW. Supply, install, terminate, energise, witnessed routine test. | C16: P-201 (SLD) / P-102 (Ground) | D16: Nr | E16: 1 | F16: 14000 | G16: =IF(OR(E16="",F16=""),"",E16*F16) | H16: 📐 Schneider / Hager / Legrand / ABB
A17: 3.2.2 | B17: SMDB-SH01: wall-mounted SMDB, IP31 powder-coated mild-steel enclosure with padlockable hinged door, 415 V / 3P+N+E, 40A TP MCCB ≥35 kA Icu incomer, busbar 40 A Cu electro-tin plated, Form 2b separation, neutral / earth bars, outgoing MCCBs / MCBs / RCBOs as per SLD, MEB sub-bar bonded to building MEB, ID-engraved circuit labels, padlockable hinged door, manufacturer's factory acceptance test (FAT) certificate. Fire-rated cable glands + LSZH gland-kits at all FR feeder terminations. Connected load 15 kW. Supply, install, terminate, energise, witnessed routine test. | C17: P-201 (SLD) | D17: Nr | E17: 1 | F17: 6000 | G17: =IF(OR(E17="",F17=""),"",E17*F17) | H17: 📐 Schneider / Hager / Legrand / ABB
A18: 3.2.3 | B18: SMDB-SH02: wall-mounted SMDB, IP31 powder-coated mild-steel enclosure with padlockable hinged door, 415 V / 3P+N+E, 40A TP MCCB ≥35 kA Icu incomer, busbar 40 A Cu electro-tin plated, Form 2b separation, neutral / earth bars, outgoing MCCBs / MCBs / RCBOs as per SLD, MEB sub-bar bonded to building MEB, ID-engraved circuit labels, padlockable hinged door, manufacturer's factory acceptance test (FAT) certificate. Fire-rated cable glands + LSZH gland-kits at all FR feeder terminations. Connected load 15 kW. Supply, install, terminate, energise, witnessed routine test. | C18: P-201 (SLD) | D18: Nr | E18: 1 | F18: 6000 | G18: =IF(OR(E18="",F18=""),"",E18*F18) | H18: 📐 Schneider / Hager / Legrand / ABB
A19: 3.2.4 | B19: SMDB-SH03: wall-mounted SMDB, IP31 powder-coated mild-steel enclosure with padlockable hinged door, 415 V / 3P+N+E, 40A TP MCCB ≥35 kA Icu incomer, busbar 40 A Cu electro-tin plated, Form 2b separation, neutral / earth bars, outgoing MCCBs / MCBs / RCBOs as per SLD, MEB sub-bar bonded to building MEB, ID-engraved circuit labels, padlockable hinged door, manufacturer's factory acceptance test (FAT) certificate. Fire-rated cable glands + LSZH gland-kits at all FR feeder terminations. Connected load 15 kW. Supply, install, terminate, energise, witnessed routine test. | C19: P-201 (SLD) | D19: Nr | E19: 1 | F19: 6000 | G19: =IF(OR(E19="",F19=""),"",E19*F19) | H19: 📐 Schneider / Hager / Legrand / ABB
A20: 3.2.5 | B20: SMDB-SH04: wall-mounted SMDB, IP31 powder-coated mild-steel enclosure with padlockable hinged door, 415 V / 3P+N+E, 40A TP MCCB ≥35 kA Icu incomer, busbar 40 A Cu electro-tin plated, Form 2b separation, neutral / earth bars, outgoing MCCBs / MCBs / RCBOs as per SLD, MEB sub-bar bonded to building MEB, ID-engraved circuit labels, padlockable hinged door, manufacturer's factory acceptance test (FAT) certificate. Fire-rated cable glands + LSZH gland-kits at all FR feeder terminations. Connected load 15 kW. Supply, install, terminate, energise, witnessed routine test. | C20: P-201 (SLD) | D20: Nr | E20: 1 | F20: 6000 | G20: =IF(OR(E20="",F20=""),"",E20*F20) | H20: 📐 Schneider / Hager / Legrand / ABB
A21: 3.2.6 | B21: SMDB-SH05: wall-mounted SMDB, IP31 powder-coated mild-steel enclosure with padlockable hinged door, 415 V / 3P+N+E, 40A TP MCCB ≥35 kA Icu incomer, busbar 40 A Cu electro-tin plated, Form 2b separation, neutral / earth bars, outgoing MCCBs / MCBs / RCBOs as per SLD, MEB sub-bar bonded to building MEB, ID-engraved circuit labels, padlockable hinged door, manufacturer's factory acceptance test (FAT) certificate. Fire-rated cable glands + LSZH gland-kits at all FR feeder terminations. Connected load 25 kW. Supply, install, terminate, energise, witnessed routine test. | C21: P-201 (SLD) | D21: Nr | E21: 1 | F21: 6000 | G21: =IF(OR(E21="",F21=""),"",E21*F21) | H21: 📐 Schneider / Hager / Legrand / ABB
A22: 3.2.7 | B22: SMDB-SH06: wall-mounted SMDB, IP31 powder-coated mild-steel enclosure with padlockable hinged door, 415 V / 3P+N+E, 40A TP MCCB ≥35 kA Icu incomer, busbar 40 A Cu electro-tin plated, Form 2b separation, neutral / earth bars, outgoing MCCBs / MCBs / RCBOs as per SLD, MEB sub-bar bonded to building MEB, ID-engraved circuit labels, padlockable hinged door, manufacturer's factory acceptance test (FAT) certificate. Fire-rated cable glands + LSZH gland-kits at all FR feeder terminations. Connected load 10 kW. Supply, install, terminate, energise, witnessed routine test. | C22: P-201 (SLD) | D22: Nr | E22: 1 | F22: 6000 | G22: =IF(OR(E22="",F22=""),"",E22*F22) | H22: 📐 Schneider / Hager / Legrand / ABB
A23: 3.2.8 | B23: SMDB-SH07: wall-mounted SMDB, IP31 powder-coated mild-steel enclosure with padlockable hinged door, 415 V / 3P+N+E, 40A TP MCCB ≥35 kA Icu incomer, busbar 40 A Cu electro-tin plated, Form 2b separation, neutral / earth bars, outgoing MCCBs / MCBs / RCBOs as per SLD, MEB sub-bar bonded to building MEB, ID-engraved circuit labels, padlockable hinged door, manufacturer's factory acceptance test (FAT) certificate. Fire-rated cable glands + LSZH gland-kits at all FR feeder terminations. Connected load 10 kW. Supply, install, terminate, energise, witnessed routine test. | C23: P-201 (SLD) | D23: Nr | E23: 1 | F23: 6000 | G23: =IF(OR(E23="",F23=""),"",E23*F23) | H23: 📐 Schneider / Hager / Legrand / ABB
A24: 3.2.9 | B24: SMDB-SH08: wall-mounted SMDB, IP31 powder-coated mild-steel enclosure with padlockable hinged door, 415 V / 3P+N+E, 40A TP MCCB ≥35 kA Icu incomer, busbar 40 A Cu electro-tin plated, Form 2b separation, neutral / earth bars, outgoing MCCBs / MCBs / RCBOs as per SLD, MEB sub-bar bonded to building MEB, ID-engraved circuit labels, padlockable hinged door, manufacturer's factory acceptance test (FAT) certificate. Fire-rated cable glands + LSZH gland-kits at all FR feeder terminations. Connected load 40 kW. Supply, install, terminate, energise, witnessed routine test. | C24: P-201 (SLD) | D24: Nr | E24: 1 | F24: 6000 | G24: =IF(OR(E24="",F24=""),"",E24*F24) | H24: 📐 Schneider / Hager / Legrand / ABB
A25: 3.2.10 | B25: SMDB-SH09: wall-mounted SMDB, IP31 powder-coated mild-steel enclosure with padlockable hinged door, 415 V / 3P+N+E, 40A TP MCCB ≥35 kA Icu incomer, busbar 40 A Cu electro-tin plated, Form 2b separation, neutral / earth bars, outgoing MCCBs / MCBs / RCBOs as per SLD, MEB sub-bar bonded to building MEB, ID-engraved circuit labels, padlockable hinged door, manufacturer's factory acceptance test (FAT) certificate. Fire-rated cable glands + LSZH gland-kits at all FR feeder terminations. Connected load 10 kW. Supply, install, terminate, energise, witnessed routine test. | C25: P-201 (SLD) | D25: Nr | E25: 1 | F25: 6000 | G25: =IF(OR(E25="",F25=""),"",E25*F25) | H25: 📐 Schneider / Hager / Legrand / ABB
A26: 3.2.11 | B26: SMDB-SH10: wall-mounted SMDB, IP31 powder-coated mild-steel enclosure with padlockable hinged door, 415 V / 3P+N+E, 40A TP MCCB ≥35 kA Icu incomer, busbar 40 A Cu electro-tin plated, Form 2b separation, neutral / earth bars, outgoing MCCBs / MCBs / RCBOs as per SLD, MEB sub-bar bonded to building MEB, ID-engraved circuit labels, padlockable hinged door, manufacturer's factory acceptance test (FAT) certificate. Fire-rated cable glands + LSZH gland-kits at all FR feeder terminations. Connected load 15 kW. Supply, install, terminate, energise, witnessed routine test. | C26: P-201 (SLD) | D26: Nr | E26: 1 | F26: 6000 | G26: =IF(OR(E26="",F26=""),"",E26*F26) | H26: 📐 Schneider / Hager / Legrand / ABB
A27: 3.2.12 | B27: SMDB-SH11: wall-mounted SMDB, IP31 powder-coated mild-steel enclosure with padlockable hinged door, 415 V / 3P+N+E, 40A TP MCCB ≥35 kA Icu incomer, busbar 40 A Cu electro-tin plated, Form 2b separation, neutral / earth bars, outgoing MCCBs / MCBs / RCBOs as per SLD, MEB sub-bar bonded to building MEB, ID-engraved circuit labels, padlockable hinged door, manufacturer's factory acceptance test (FAT) certificate. Fire-rated cable glands + LSZH gland-kits at all FR feeder terminations. Connected load 15 kW. Supply, install, terminate, energise, witnessed routine test. | C27: P-201 (SLD) | D27: Nr | E27: 1 | F27: 6000 | G27: =IF(OR(E27="",F27=""),"",E27*F27) | H27: 📐 Schneider / Hager / Legrand / ABB
A28: 3.2.13 | B28: SMDB-SH12: wall-mounted SMDB, IP31 powder-coated mild-steel enclosure with padlockable hinged door, 415 V / 3P+N+E, 63A TP MCCB ≥35 kA Icu incomer, busbar 63 A Cu electro-tin plated, Form 2b separation, neutral / earth bars, outgoing MCCBs / MCBs / RCBOs as per SLD, MEB sub-bar bonded to building MEB, ID-engraved circuit labels, padlockable hinged door, manufacturer's factory acceptance test (FAT) certificate. Fire-rated cable glands + LSZH gland-kits at all FR feeder terminations. Connected load 30 kW. Supply, install, terminate, energise, witnessed routine test. | C28: P-201 (SLD) | D28: Nr | E28: 1 | F28: 9000 | G28: =IF(OR(E28="",F28=""),"",E28*F28) | H28: 📐 Schneider / Hager / Legrand / ABB
A29: Sub-Total 3.2 | G29: =SUM(G16:G29)
A31: 3.3 — ROOF SMDBs
A32: 3.3.1 | B32: SMDB-RF: floor-standing SMDB, IP65 stainless-steel 316L weatherproof enclosure with UV-resistant gland kits and sun-shield canopy, 415 V / 3P+N+E, 500A TP MCCB ≥35 kA Icu incomer, busbar 500 A Cu electro-tin plated, Form 2b separation, neutral / earth bars, outgoing MCCBs / MCBs / RCBOs as per SLD, MEB sub-bar bonded to building MEB, ID-engraved circuit labels, padlockable hinged door, manufacturer's factory acceptance test (FAT) certificate. Fire-rated cable glands + LSZH gland-kits at all FR feeder terminations. Connected load 248.63 kW. Supply, install, terminate, energise, witnessed routine test. | C32: P-201 (SLD) / P-106 (Roof) | D32: Nr | E32: 1 | F32: 79200 | G32: =IF(OR(E32="",F32=""),"",E32*F32) | H32: 📐 Schneider / Hager / Legrand / ABB
A33: Sub-Total 3.3 | G33: =SUM(G32:G33)
A35: 3.4 — SPECIAL-DUTY SMDBs (EV / Lift / etc.)
A36: 3.4.1 | B36: SMDB-EV: wall-mounted SMDB, IP54 powder-coated mild-steel enclosure (epoxy-polyester finish), splash + dust-protected, 415 V / 3P+N+E, 160A TP MCCB ≥35 kA Icu incomer, busbar 160 A Cu electro-tin plated, Form 2b separation, neutral / earth bars, outgoing MCCBs / MCBs / RCBOs as per SLD, MEB sub-bar bonded to building MEB, ID-engraved circuit labels, padlockable hinged door, manufacturer's factory acceptance test (FAT) certificate. Fire-rated cable glands + LSZH gland-kits at all FR feeder terminations. Connected load 88 kW. Supply, install, terminate, energise, witnessed routine test. | C36: P-201 (SLD) / P-101 (Basement) | D36: Nr | E36: 1 | F36: 16520 | G36: =IF(OR(E36="",F36=""),"",E36*F36) | H36: 📐 Schneider / Hager / Legrand / ABB
A37: Sub-Total 3.4 | G37: =SUM(G36:G37)
A39: 3.5 — RETAIL SMDBs
A40: 3.5.1 | B40: SMDB-SH01: wall-mounted SMDB, IP31 powder-coated mild-steel enclosure with padlockable hinged door, 415 V / 3P+N+E, 40A TP MCCB ≥35 kA Icu incomer, busbar 40 A Cu electro-tin plated, Form 2b separation, neutral / earth bars, outgoing MCCBs / MCBs / RCBOs as per SLD, MEB sub-bar bonded to building MEB, ID-engraved circuit labels, padlockable hinged door, manufacturer's factory acceptance test (FAT) certificate. Fire-rated cable glands + LSZH gland-kits at all FR feeder terminations. Connected load 15 kW. Supply, install, terminate, energise, witnessed routine test. | C40: P-201 (SLD) | D40: Nr | E40: 1 | F40: 6000 | G40: =IF(OR(E40="",F40=""),"",E40*F40) | H40: 📐 Schneider / Hager / Legrand / ABB
A41: 3.5.2 | B41: SMDB-SH02: wall-mounted SMDB, IP31 powder-coated mild-steel enclosure with padlockable hinged door, 415 V / 3P+N+E, 40A TP MCCB ≥35 kA Icu incomer, busbar 40 A Cu electro-tin plated, Form 2b separation, neutral / earth bars, outgoing MCCBs / MCBs / RCBOs as per SLD, MEB sub-bar bonded to building MEB, ID-engraved circuit labels, padlockable hinged door, manufacturer's factory acceptance test (FAT) certificate. Fire-rated cable glands + LSZH gland-kits at all FR feeder terminations. Connected load 15 kW. Supply, install, terminate, energise, witnessed routine test. | C41: P-201 (SLD) | D41: Nr | E41: 1 | F41: 6000 | G41: =IF(OR(E41="",F41=""),"",E41*F41) | H41: 📐 Schneider / Hager / Legrand / ABB
A42: 3.5.3 | B42: SMDB-SH03: wall-mounted SMDB, IP31 powder-coated mild-steel enclosure with padlockable hinged door, 415 V / 3P+N+E, 40A TP MCCB ≥35 kA Icu incomer, busbar 40 A Cu electro-tin plated, Form 2b separation, neutral / earth bars, outgoing MCCBs / MCBs / RCBOs as per SLD, MEB sub-bar bonded to building MEB, ID-engraved circuit labels, padlockable hinged door, manufacturer's factory acceptance test (FAT) certificate. Fire-rated cable glands + LSZH gland-kits at all FR feeder terminations. Connected load 15 kW. Supply, install, terminate, energise, witnessed routine test. | C42: P-201 (SLD) | D42: Nr | E42: 1 | F42: 6000 | G42: =IF(OR(E42="",F42=""),"",E42*F42) | H42: 📐 Schneider / Hager / Legrand / ABB
A43: 3.5.4 | B43: SMDB-SH04: wall-mounted SMDB, IP31 powder-coated mild-steel enclosure with padlockable hinged door, 415 V / 3P+N+E, 40A TP MCCB ≥35 kA Icu incomer, busbar 40 A Cu electro-tin plated, Form 2b separation, neutral / earth bars, outgoing MCCBs / MCBs / RCBOs as per SLD, MEB sub-bar bonded to building MEB, ID-engraved circuit labels, padlockable hinged door, manufacturer's factory acceptance test (FAT) certificate. Fire-rated cable glands + LSZH gland-kits at all FR feeder terminations. Connected load 15 kW. Supply, install, terminate, energise, witnessed routine test. | C43: P-201 (SLD) | D43: Nr | E43: 1 | F43: 6000 | G43: =IF(OR(E43="",F43=""),"",E43*F43) | H43: 📐 Schneider / Hager / Legrand / ABB
A44: 3.5.5 | B44: SMDB-SH05: wall-mounted SMDB, IP31 powder-coated mild-steel enclosure with padlockable hinged door, 415 V / 3P+N+E, 40A TP MCCB ≥35 kA Icu incomer, busbar 40 A Cu electro-tin plated, Form 2b separation, neutral / earth bars, outgoing MCCBs / MCBs / RCBOs as per SLD, MEB sub-bar bonded to building MEB, ID-engraved circuit labels, padlockable hinged door, manufacturer's factory acceptance test (FAT) certificate. Fire-rated cable glands + LSZH gland-kits at all FR feeder terminations. Connected load 25 kW. Supply, install, terminate, energise, witnessed routine test. | C44: P-201 (SLD) | D44: Nr | E44: 1 | F44: 6000 | G44: =IF(OR(E44="",F44=""),"",E44*F44) | H44: 📐 Schneider / Hager / Legrand / ABB
...

Sheet Bill 4 - Distribution Boards
A1: BILL No. 4 — DISTRIBUTION BOARDS (DBS) & CONSUMER UNITS
A2: Project: Proposed B+G+8+R Commercial & Residential Building, Plot 6731315, Al Barsha South Third, Dubai, UAE | Job: FA_P379 / CRs B/010/25 | Authority: DEWA (Dubai Electricity & Water Authority)
A3: Item | B3: Description | C3: Reference | D3: Unit | E3: Qty | F3: Rate (AED) | G3: Amount (AED) | H3: Origin / Brand
A4: 4.1 — DISTRIBUTION BOARDS (per cable schedule)
A5: 4.1.1 | B5: DB-G: DB fed from SMDB-G, 63A TP incomer, IP4X. Supply, install, terminate, label, test & commission. | C5: P-201 (SLD) / Floor plan | D5: Nr | E5: 1 | F5: 9000 | G5: =IF(OR(E5="",F5=""),"",E5*F5) | H5: 📐 Schneider / Hager / Legrand / ABB
A6: 4.1.2 | B6: DB-F1: DB fed from SMDB-G, 40A TP incomer, IP4X. Supply, install, terminate, label, test & commission. | C6: P-201 (SLD) / Floor plan | D6: Nr | E6: 1 | F6: 6000 | G6: =IF(OR(E6="",F6=""),"",E6*F6) | H6: 📐 Schneider / Hager / Legrand / ABB
A7: 4.1.3 | B7: DB-F4: DB fed from SMDB-G, 40A TP incomer, IP4X. Supply, install, terminate, label, test & commission. | C7: P-201 (SLD) / Floor plan | D7: Nr | E7: 1 | F7: 6000 | G7: =IF(OR(E7="",F7=""),"",E7*F7) | H7: 📐 Schneider / Hager / Legrand / ABB
A8: 4.1.4 | B8: DB-F5: DB fed from SMDB-G, 40A TP incomer, IP4X. Supply, install, terminate, label, test & commission. | C8: P-201 (SLD) / Floor plan | D8: Nr | E8: 1 | F8: 6000 | G8: =IF(OR(E8="",F8=""),"",E8*F8) | H8: 📐 Schneider / Hager / Legrand / ABB
A9: 4.1.5 | B9: DB-L.GYM: DB fed from SMDB-RF, 40A TP incomer, IP4X. Supply, install, terminate, label, test & commission. | C9: P-106 (Roof) / P-201 (SLD) | D9: Nr | E9: 1 | F9: 6000 | G9: =IF(OR(E9="",F9=""),"",E9*F9) | H9: 📐 Schneider / Hager / Legrand / ABB
A10: 4.1.6 | B10: DB-G.GYM: DB fed from SMDB-RF, 40A TP incomer, IP4X. Supply, install, terminate, label, test & commission. | C10: P-106 (Roof) / P-201 (SLD) | D10: Nr | E10: 1 | F10: 6000 | G10: =IF(OR(E10="",F10=""),"",E10*F10) | H10: 📐 Schneider / Hager / Legrand / ABB
A11: 4.1.7 | B11: DB-WM: DB fed from SMDB-RF, 40A TP incomer, IP4X. Supply, install, terminate, label, test & commission. | C11: P-106 (Roof) / P-201 (SLD) | D11: Nr | E11: 1 | F11: 6000 | G11: =IF(OR(E11="",F11=""),"",E11*F11) | H11: 📐 Schneider / Hager / Legrand / ABB
A12: 4.1.8 | B12: EDB-G: DB fed from ESMDB-G, 40A TP incomer, IP4X. Supply, install, terminate, label, test & commission. | C12: P-201 (Emergency) / Floor plan | D12: Nr | E12: 1 | F12: 6900 | G12: =IF(OR(E12="",F12=""),"",E12*F12) | H12: 📐 Schneider / Hager / Legrand / ABB
A13: 4.1.9 | B13: EDB-1F: DB fed from ESMDB-G, 32A TP incomer, IP4X. Supply, install, terminate, label, test & commission. | C13: P-201 (Emergency) / Floor plan | D13: Nr | E13: 1 | F13: 6900 | G13: =IF(OR(E13="",F13=""),"",E13*F13) | H13: 📐 Schneider / Hager / Legrand / ABB
A14: 4.1.10 | B14: EDB-TEL: DB fed from ESMDB-G, 40A TP incomer, IP4X. Supply, install, terminate, label, test & commission. | C14: P-201 (Emergency) / Floor plan | D14: Nr | E14: 1 | F14: 6900 | G14: =IF(OR(E14="",F14=""),"",E14*F14) | H14: 📐 Schneider / Hager / Legrand / ABB
A15: 4.1.11 | B15: EDB-PR: DB fed from ESMDB-G, 40A TP incomer, IP4X. Supply, install, terminate, label, test & commission. | C15: P-201 (Emergency) / Floor plan | D15: Nr | E15: 1 | F15: 6900 | G15: =IF(OR(E15="",F15=""),"",E15*F15) | H15: 📐 Schneider / Hager / Legrand / ABB
A16: 4.1.12 | B16: EDB-4F: DB fed from ESMDB-RF, 40A TP incomer, IP4X. Supply, install, terminate, label, test & commission. | C16: P-106 (Roof) / P-201 (SLD) | D16: Nr | E16: 1 | F16: 6900 | G16: =IF(OR(E16="",F16=""),"",E16*F16) | H16: 📐 Schneider / Hager / Legrand / ABB
... A60: 4.1.56 | B60: DB-SHOP12: DB fed from SMDB-SH01 to SMDB-SH12, TP incomer, IP4X. Supply, install, terminate, label, test & commission. | C60: P-201 (SLD) / Floor plan | D60: Nr | E60: 1 | F60: 12000 | G60: =IF(OR(E60="",F60=""),"",E60*F60) | H60: 📐 Schneider / Hager / Legrand / ABB
A61: Sub-Total 4.1 | G61: =SUM(G5:G61)
A64: BILL 4 — TOTAL CARRIED TO SUMMARY | G64: =SUMIF(G4:G62,"<>")

Sheet Bill 5 - LV Cables
A1: BILL No. 5 — LV POWER CABLES (Main + Distribution + Final Circuits)
A2: Project: Proposed B+G+8+R Commercial & Residential Building, Plot 6731315, Al Barsha South Third, Dubai, UAE | Job: FA_P379 / CRs B/010/25 | Authority: DEWA (Dubai Electricity & Water Authority)
A3: Item | B3: Cable Size | C3: Description (Route & Scope) | D3: Reference | E3: Unit | F3: Qty | G3: Rate (AED) | H3: Amount (AED) | I3: Origin / Brand
A4: 5.1 — XLPE / SWA / PVC LV CABLES — Plant & Utility Risers (LV Panel → SMDB)
A5: Spec (all rows in this section): XLPE / SWA / PVC 600/1000 V armoured cable to BS 5467 / IEC 60502, on plant / utility risers (non-public-area, non-escape-route). Installed in cable tray / ladder / conduit incl. fire stopping at penetrations, BW-type brass glands with shrouds, compression lugs, ferrules and terminations at both ends.
A6: 5.1.1 | B6: 4C×150mm² XLPE/SWA/PVC | C6: LVP-01 → SMDB-1F — plant / utility riser | D6: P-200 (SLD) / P-010 (Cable tray) | E6: m | F6: 25 | G6: 195 | H6: =IF(OR(F6="",G6=""),"",F6*G6) | I6: 📐 Ducab / NCC / Oman Cables / Riyadh Cables
A7: 5.1.2 | B7: 4C×150mm² XLPE/SWA/PVC | C7: LVP-01 → SMDB-2F — plant / utility riser | D7: P-200 (SLD) / P-010 (Cable tray) | E7: m | F7: 29 | G7: 195 | H7: =IF(OR(F7="",G7=""),"",F7*G7) | I7: 📐 Ducab / NCC / Oman Cables / Riyadh Cables
A8: 5.1.3 | B8: 4C×150mm² XLPE/SWA/PVC | C8: LVP-01 → SMDB-3F — plant / utility riser | D8: P-200 (SLD) / P-010 (Cable tray) | E8: m | F8: 33 | G8: 195 | H8: =IF(OR(F8="",G8=""),"",F8*G8) | I8: 📐 Ducab / NCC / Oman Cables / Riyadh Cables
A9: 5.1.4 | B9: 4C×150mm² XLPE/SWA/PVC | C9: LVP-01 → SMDB-4F — plant / utility riser | D9: P-200 (SLD) / P-010 (Cable tray) | E9: m | F9: 37 | G9: 195 | H9: =IF(OR(F9="",G9=""),"",F9*G9) | I9: 📐 Ducab / NCC / Oman Cables / Riyadh Cables
A10: 5.1.5 | B10: 4C×150mm² XLPE/SWA/PVC | C10: LVP-01 → SMDB-5F — plant / utility riser | D10: P-200 (SLD) / P-010 (Cable tray) | E10: m | F10: 41 | G10: 195 | H10: =IF(OR(F10="",G10=""),"",F10*G10) | I10: 📐 Ducab / NCC / Oman Cables / Riyadh Cables
A11: 5.1.6 | B11: 4C×150mm² XLPE/SWA/PVC | C11: LVP-01 → SMDB-6F — plant / utility riser | D11: P-200 (SLD) / P-010 (Cable tray) | E11: m | F11: 45 | G11: 195 | H11: =IF(OR(F11="",G11=""),"",F11*G11) | I11: 📐 Ducab / NCC / Oman Cables / Riyadh Cables
A12: 5.1.7 | B12: 4C×150mm² XLPE/SWA/PVC | C12: LVP-01 → SMDB-7F — plant / utility riser | D12: P-200 (SLD) / P-010 (Cable tray) | E12: m | F12: 49 | G12: 195 | H12: =IF(OR(F12="",G12=""),"",F12*G12) | I12: 📐 Ducab / NCC / Oman Cables / Riyadh Cables
A13: 5.1.8 | B13: 4C×150mm² XLPE/SWA/PVC | C13: LVP-01 → SMDB-8F — plant / utility riser | D13: P-200 (SLD) / P-010 (Cable tray) | E13: m | F13: 53 | G13: 195 | H13: =IF(OR(F13="",G13=""),"",F13*G13) | I13: 📐 Ducab / NCC / Oman Cables / Riyadh Cables
A14: 5.1.9 | B14: 4C×150mm² XLPE/SWA/PVC | C14: LVP-02 → SMDB-RF — plant / utility riser | D14: P-200 (SLD) / P-010 (Cable tray) | E14: m | F14: 65 | G14: 195 | H14: =IF(OR(F14="",G14=""),"",F14*G14) | I14: 📐 Ducab / NCC / Oman Cables / Riyadh Cables
A15: 5.1.10 | B15: 4C×50mm² XLPE/SWA/PVC | C15: LVP-02 → SMDB-G — plant / utility riser | D15: P-200 (SLD) / P-010 (Cable tray) | E15: m | F15: 15 | G15: 85 | H15: =IF(OR(F15="",G15=""),"",F15*G15) | I15: 📐 Ducab / NCC / Oman Cables / Riyadh Cables
A16: 5.1.11 | B16: 4C×70mm² XLPE/SWA/PVC | C16: LVP-02 → SMDB-EV — plant / utility riser | D16: P-200 (SLD) / P-010 (Cable tray) | E16: m | F16: 20 | G16: 110 | H16: =IF(OR(F16="",G16=""),"",F16*G16) | I16: 📐 Ducab / NCC / Oman Cables / Riyadh Cables
A17: 5.1.12 | B17: 4C×10mm² XLPE/SWA/PVC | C17: LVP-02 → SMDB-SH01 — plant / utility riser | D17: P-200 (SLD) / P-010 (Cable tray) | E17: m | F17: 20 | G17: 22 | H17: =IF(OR(F17="",G17=""),"",F17*G17) | I17: 📐 Ducab / NCC / Oman Cables / Riyadh Cables
... A28: 5.1.23 | B28: 4C×16mm² XLPE/SWA/PVC | C28: LVP-02 → SMDB-SH12 — plant / utility riser | D28: P-200 (SLD) / P-010 (Cable tray) | E28: m | F28: 42 | G28: 32 | H28: =IF(OR(F28="",G28=""),"",F28*G28) | I28: 📐 Ducab / NCC / Oman Cables / Riyadh Cables
A29: Sub-Total 5.1 | H29: =SUM(H6:H29)
A31: 5.2 — FIRE-RATED LSZH CABLES (BS 6387 CWZ / IEC 60331-21 — life-safety circuits)
A32: Spec (all rows in this section): Fire-Rated LSZH cable to BS 6387 CWZ / IEC 60331-21 (950 °C / 3 h circuit integrity); LSZH outer jacket per BS 7211 / IEC 60332-3 Cat C / IEC 61034 / IEC 60754. Dedicated fire-rated containment, FR cleats at max 300 mm centres, FR/LSZH glands, FR terminations, red ID labels.
A33: 5.2.1 | B33: 4C×70mm² FR/LSZH | C33: LVP-02 → ESMDB-G — life-safety circuit | D33: P-200 (SLD) / P-010 (Cable tray) | E33: m | F33: 15 | G33: 229 | H33: =IF(OR(F33="",G33=""),"",F33*G33) | I33: 📐 Ducab FR / Pirelli / Prysmian / Nexans
A34: 5.2.2 | B34: 4C×185mm² FR/LSZH | C34: LVP-02 → Fire Pump — life-safety circuit | D34: P-200 (SLD) / P-010 (Cable tray) | E34: m | F34: 35 | G34: 510 | H34: =IF(OR(F34="",G34=""),"",F34*G34) | I34: 📐 Ducab FR / Pirelli / Prysmian / Nexans
A35: Sub-Total 5.2 | H35: =SUM(H33:H35)
A37: 5.3 — DISTRIBUTION CABLES (SMDB → DB) — XLPE / SWA / PVC
A38: Spec (all rows in this section): XLPE / SWA / PVC 600/1000 V armoured cable to BS 5467 / IEC 60502, on plant / utility risers (non-public-area, non-escape-route). Installed in cable tray / ladder / conduit incl. fire stopping at penetrations, BW-type brass glands with shrouds, compression lugs, ferrules and terminations at both ends.
A39: 5.3.1 | B39: 4C×16mm² XLPE/SWA/PVC | C39: SMDB-G → DB-G — SMDB → DB distribution | D39: P-201 (SLD) / Floor plan | E39: m | F39: 20 | G39: 32 | H39: =IF(OR(F39="",G39=""),"",F39*G39) | I39: 📐 Ducab / NCC / Oman Cables / Riyadh Cables
A40: 5.3.2 | B40: 4C×10mm² XLPE/SWA/PVC | C40: SMDB-G → DB-F1 — SMDB → DB distribution | D40: P-201 (SLD) / Floor plan | E40: m | F40: 15 | G40: 22 | H40: =IF(OR(F40="",G40=""),"",F40*G40) | I40: 📐 Ducab / NCC / Oman Cables / Riyadh Cables
A41: 5.3.3 | B41: 4C×10mm² XLPE/SWA/PVC | C41: SMDB-G → DB-F4 — SMDB → DB distribution | D41: P-201 (SLD) / Floor plan | E41: m | F41: 15 | G41: 22 | H41: =IF(OR(F41="",G41=""),"",F41*G41) | I41: 📐 Ducab / NCC / Oman Cables / Riyadh Cables
A42: 5.3.4 | B42: 4C×10mm² XLPE/SWA/PVC | C42: SMDB-G → DB-F5 — SMDB → DB distribution | D42: P-201 (SLD) / Floor plan | E42: m | F42: 15 | G42: 22 | H42: =IF(OR(F42="",G42=""),"",F42*G42) | I42: 📐 Ducab / NCC / Oman Cables / Riyadh Cables
A43: 5.3.5 | B43: 4C×10mm² XLPE/SWA/PVC | C43: SMDB-RF → DB-L.GYM — SMDB → DB distribution | D43: P-201 (SLD) / Floor plan | E43: m | F43: 20 | G43: 22 | H43: =IF(OR(F43="",G43=""),"",F43*G43) | I43: 📐 Ducab / NCC / Oman Cables / Riyadh Cables
A44: 5.3.6 | B44: 4C×10mm² XLPE/SWA/PVC | C44: SMDB-RF → DB-G.GYM — SMDB → DB distribution | D44: P-201 (SLD) / Floor plan | E44: m | F44: 20 | G44: 22 | H44: =IF(OR(F44="",G44=""),"",F44*G44) | I44: 📐 Ducab / NCC / Oman Cables / Riyadh Cables
A45: 5.3.7 | B45: 4C×10mm² XLPE/SWA/PVC | C45: SMDB-RF → DB-WM — SMDB → DB distribution | D45: P-201 (SLD) / Floor plan | E45: m | F45: 15 | G45: 22 | H45: =IF(OR(F45="",G45=""),"",F45*G45) | I45: 📐 Ducab / NCC / Oman Cables / Riyadh Cables
A46: 5.3.8 | B46: 4C×10mm² XLPE/SWA/PVC | C46: ESMDB-G → EDB-G — SMDB → DB distribution | D46: P-201 (SLD) / Floor plan | E46: m | F46: 15 | G46: 22 | H46: =IF(OR(F46="",G46=""),"",F46*G46) | I46: 📐 Ducab / NCC / Oman Cables / Riyadh Cables
A47: 5.3.9 | B47: 4C×6mm² XLPE/SWA/PVC | C47: ESMDB-G → EDB-1F — SMDB → DB distribution | D47: P-201 (SLD) / Floor plan | E47: m | F47: 25 | G47: 14 | H47: =IF(OR(F47="",G47=""),"",F47*G47) | I47: 📐 Ducab / NCC / Oman Cables / Riyadh Cables
A48: 5.3.10 | B48: 4C×10mm² XLPE/SWA/PVC | C48: ESMDB-G → EDB-TEL — SMDB → DB distribution | D48: P-201 (SLD) / Floor plan | E48: m | F48: 15 | G48: 22 | H48: =IF(OR(F48="",G48=""),"",F48*G48) | I48: 📐 Ducab / NCC / Oman Cables / Riyadh Cables
A49: 5.3.11 | B49: 4C×10mm² XLPE/SWA/PVC | C49: ESMDB-G → EDB-PR — SMDB → DB distribution | D49: P-201 (SLD) / Floor plan | E49: m | F49: 30 | G49: 22 | H49: =IF(OR(F49="",G49=""),"",F49*G49) | I49: 📐 Ducab / NCC / Oman Cables / Riyadh Cables
A50: 5.3.12 | B50: 4C×10mm² XLPE/SWA/PVC | C50: ESMDB-RF → EDB-4F — SMDB → DB distribution | D50: P-201 (SLD) / Floor plan | E50: m | F50: 20 | G50: 22 | H50: =IF(OR(F50="",G50=""),"",F50*G50) | I50: 📐 Ducab / NCC / Oman Cables / Riyadh Cables
... A172: 5.3.134 | B172: 4C×16mm² XLPE/SWA/PVC | C172: SMDB-8F → DB-T15 — SMDB → DB distribution | D172: P-201 (SLD) / Floor plan | E172: m | F172: 25 | G172: 32 | H172: =IF(OR(F172="",G172=""),"",F172*G172) | I172: 📐 Ducab / NCC / Oman Cables / Riyadh Cables
A173: Sub-Total 5.3 | H173: =SUM(H39:H173)
...

Sheet Bill 6 - Containment
A1: BILL No. 6 — CABLE CONTAINMENT (TRAY, LADDER, TRUNKING, CONDUIT)
A2: Project: Proposed B+G+8+R Commercial & Residential Building, Plot 6731315, Al Barsha South Third, Dubai, UAE | Job: FA_P379 / CRs B/010/25 | Authority: DEWA (Dubai Electricity & Water Authority)
A3: Item | B3: Description | C3: Reference | D3: Unit | E3: Qty | F3: Rate (AED) | G3: Amount (AED) | H3: Origin / Brand
A4: 6.1 — CABLE TRAYS, LADDERS, TRUNKING & CONDUITS
A5: 6.1.1 | B5: 300mm wide HDGI cable tray — LV room + main vertical risers, hot-dip galvanised to BS EN ISO 1461, c/w supports at max 1.5m centres on horizontal / 1.0m on vertical, brackets, bends, tees, reducers, copplers, fixings, earth bonding straps. | C5: P-010 (Cable tray detail) / P-201 | D5: m | E5: 180 | F5: 385 | G5: =IF(OR(E5="",F5=""),"",E5*F5) | H5: 📋 Marshall Tufflex / Vergokan / Niedax / Eltete
A6: 6.1.2 | B6: 150mm wide HDGI cable tray — SMDB to DB horizontal distribution, hot-dip galvanised to BS EN ISO 1461, c/w supports at max 1.5m centres on horizontal / 1.0m on vertical, brackets, bends, tees, reducers, copplers, fixings, earth bonding straps. | C6: P-010 (Cable tray detail) / P-201 | D6: m | E6: 320 | F6: 195 | G6: =IF(OR(E6="",F6=""),"",E6*F6) | H6: 📋 Marshall Tufflex / Vergokan / Niedax / Eltete
A7: 6.1.3 | B7: 100mm wide HDGI cable tray — branch distribution, hot-dip galvanised to BS EN ISO 1461, c/w supports at max 1.5m centres on horizontal / 1.0m on vertical, brackets, bends, tees, reducers, copplers, fixings, earth bonding straps. | C7: P-010 (Cable tray detail) / P-201 | D7: m | E7: 250 | F7: 160 | G7: =IF(OR(E7="",F7=""),"",E7*F7) | H7: 📋 Marshall Tufflex / Vergokan / Niedax / Eltete
A8: 6.1.4 | B8: 100×100mm GI trunking — riser shafts, hot-dip galvanised to BS EN ISO 1461, c/w supports at max 1.5m centres on horizontal / 1.0m on vertical, brackets, bends, tees, reducers, copplers, fixings, earth bonding straps. | C8: P-010 (Cable tray detail) / P-201 | D8: m | E8: 120 | F8: 160 | G8: =IF(OR(E8="",F8=""),"",E8*F8) | H8: 📋 Marshall Tufflex / Pemsa / Atkore / DSS
A9: 6.1.5 | B9: Ø25mm GI conduit — exposed / mechanical equipment & wet areas, hot-dip galvanised to BS EN ISO 1461, c/w supports at max 1.5m centres on horizontal / 1.0m on vertical, brackets, bends, tees, reducers, copplers, fixings, earth bonding straps. | C9: P-010 (Cable tray detail) / P-201 | D9: m | E9: 600 | F9: 48 | G9: =IF(OR(E9="",F9=""),"",E9*F9) | H9: 📋 Marshall Tufflex / Pemsa / Atkore / DSS
A10: 6.1.6 | B10: Ø25mm PVC conduit — concealed sub-mains, hot-dip galvanised to BS EN ISO 1461, c/w supports at max 1.5m centres on horizontal / 1.0m on vertical, brackets, bends, tees, reducers, copplers, fixings, earth bonding straps. | C10: P-010 (Cable tray detail) / P-201 | D10: m | E10: 2800 | F10: 48 | G10: =IF(OR(E10="",F10=""),"",E10*F10) | H10: 📋 Marshall Tufflex / Pemsa / Atkore / DSS
A11: 6.1.7 | B11: Ø20mm PVC conduit — concealed final circuits to outlets & lighting points, hot-dip galvanised to BS EN ISO 1461, c/w supports at max 1.5m centres on horizontal / 1.0m on vertical, brackets, bends, tees, reducers, copplers, fixings, earth bonding straps. | C11: P-010 (Cable tray detail) / P-201 | D11: m | E11: 9000 | F11: 48 | G11: =IF(OR(E11="",F11=""),"",E11*F11) | H11: 📋 Marshall Tufflex / Pemsa / Atkore / DSS
A12: 6.1.8 | B12: Pull boxes at every 15m of conduit run or two 90° bends (General Note 14), hot-dip galvanised to BS EN ISO 1461, c/w supports at max 1.5m centres on horizontal / 1.0m on vertical, brackets, bends, tees, reducers, copplers, fixings, earth bonding straps. | C12: P-010 (Cable tray detail) / P-201 | D12: Nr | E12: 400 | F12: 24 | G12: =IF(OR(E12="",F12=""),"",E12*F12) | H12: 📋 Marshall Tufflex / Pemsa / Atkore / DSS
A13: Sub-Total 6.1 | G13: =SUM(G5:G13)
A16: BILL 6 — TOTAL CARRIED TO SUMMARY | G16: =SUMIF(G4:G14,"<>")

Sheet Bill 7 - Wiring Devices
A1: BILL No. 7 — WIRING DEVICES & ACCESSORIES
A2: Project: Proposed B+G+8+R Commercial & Residential Building, Plot 6731315, Al Barsha South Third, Dubai, UAE | Job: FA_P379 / CRs B/010/25 | Authority: DEWA (Dubai Electricity & Water Authority)
A3: Item | B3: Description | C3: Reference | D3: Unit | E3: Qty | F3: Rate (AED) | G3: Amount (AED) | H3: Origin / Brand
A4: 7.1 — BASEMENT — SOCKET OUTLETS & SMALL POWER
A5: 7.1.1 | B5: 13A 230V weatherproof IP55 socket outlet | C5: P-103 … P-108 (Floor plans) | D5: Nr | E5: 40 | F5: 95 | G5: =IF(OR(E5="",F5=""),"",E5*F5) | H5: 📋 MK / Schneider / Legrand / Hager
A6: 7.1.2 | B6: 13A 230V SP switched socket outlet (BS 1363) | C6: P-103 … P-108 (Floor plans) | D6: Nr | E6: 16 | F6: 45 | G6: =IF(OR(E6="",F6=""),"",E6*F6) | H6: 📋 MK / Schneider / Legrand / Hager
A7: 7.1.3 | B7: 20A 230V DP switch — water heater / cooker isolation | C7: P-103 … P-108 (Floor plans) | D7: Nr | E7: 6 | F7: 85 | G7: =IF(OR(E7="",F7=""),"",E7*F7) | H7: 📋 MK / Schneider / Legrand / Hager
A8: Sub-Total 7.1 — Basement | G8: =SUM(G5:G8)
A10: 7.2 — GROUND FLOOR — SOCKET OUTLETS & SMALL POWER
A11: 7.2.1 | B11: 13A 230V SP switched socket outlet (BS 1363) | C11: P-103 … P-108 (Floor plans) | D11: Nr | E11: 40 | F11: 45 | G11: =IF(OR(E11="",F11=""),"",E11*F11) | H11: 📋 MK / Schneider / Legrand / Hager
A12: 7.2.2 | B12: 13A 230V twin switched socket outlet (BS 1363) | C12: P-103 … P-108 (Floor plans) | D12: Nr | E12: 28 | G12: =IF(OR(E12="",F12=""),"",E12*F12) | H12: 📋 MK / Schneider / Legrand / Hager
A13: 7.2.3 | B13: 13A 230V weatherproof IP55 socket outlet | C13: P-103 … P-108 (Floor plans) | D13: Nr | E13: 20 | F13: 95 | G13: =IF(OR(E13="",F13=""),"",E13*F13) | H13: 📋 MK / Schneider / Legrand / Hager
A14: 7.2.4 | B14: Floor box — 13A twin socket + RJ45 dual outlet | C14: P-103 … P-108 (Floor plans) | D14: Nr | E14: 18 | F14: 75 | G14: =IF(OR(E14="",F14=""),"",E14*F14) | H14: 📋 MK / Schneider / Legrand / Hager
A15: 7.2.5 | B15: 13A flex outlet for hand dryer (common WCs) | C15: P-103 … P-108 (Floor plans) | D15: Nr | E15: 8 | G15: =IF(OR(E15="",F15=""),"",E15*F15) | H15: 📋 MK / Schneider / Legrand / Hager
A16: 7.2.6 | B16: 13A switched fused spur with neon for FCU (AC indoor unit) | C16: P-103 … P-108 (Floor plans) | D16: Nr | E16: 6 | F16: 45 | G16: =IF(OR(E16="",F16=""),"",E16*F16) | H16: 📋 MK / Schneider / Legrand / Hager
A17: Sub-Total 7.2 — Ground Floor | G17: =SUM(G11:G17)
A19: 7.3 — 1F — SOCKET OUTLETS & SMALL POWER
A20: 7.3.1 | B20: 13A 230V SP switched socket outlet (BS 1363) | C20: P-103 … P-108 (Floor plans) | D20: Nr | E20: 88 | F20: 45 | G20: =IF(OR(E20="",F20=""),"",E20*F20) | H20: 📋 MK / Schneider / Legrand / Hager
A21: 7.3.2 | B21: 13A 230V twin switched socket outlet (BS 1363) | C21: P-103 … P-108 (Floor plans) | D21: Nr | E21: 162 | G21: =IF(OR(E21="",F21=""),"",E21*F21) | H21: 📋 MK / Schneider / Legrand / Hager
A22: 7.3.3 | B22: 13A 230V twin switched socket outlet + USB-A/USB-C ports | C22: P-103 … P-108 (Floor plans) | D22: Nr | E22: 30 | F22: 180 | G22: =IF(OR(E22="",F22=""),"",E22*F22) | H22: 📋 MK / Schneider / Legrand / Hager
A23: 7.3.4 | B23: 13A 230V weatherproof IP55 socket outlet | C23: P-103 … P-108 (Floor plans) | D23: Nr | E23: 30 | F23: 95 | G23: =IF(OR(E23="",F23=""),"",E23*F23) | H23: 📋 MK / Schneider / Legrand / Hager
A24: 7.3.5 | B24: 20A 230V flex outlet for water heater (with neon) | C24: P-103 … P-108 (Floor plans) | D24: Nr | E24: 22 | G24: =IF(OR(E24="",F24=""),"",E24*F24) | H24: 📋 MK / Schneider / Legrand / Hager
A25: 7.3.6 | B25: 20A 230V DP switch — water heater / cooker isolation | C25: P-103 … P-108 (Floor plans) | D25: Nr | E25: 30 | F25: 85 | G25: =IF(OR(E25="",F25=""),"",E25*F25) | H25: 📋 MK / Schneider / Legrand / Hager
A26: 7.3.7 | B26: 13A switched fused spur with neon for FCU (AC indoor unit) | C26: P-103 … P-108 (Floor plans) | D26: Nr | E26: 48 | F26: 45 | G26: =IF(OR(E26="",F26=""),"",E26*F26) | H26: 📋 MK / Schneider / Legrand / Hager
A27: 7.3.8 | B27: 13A flex outlet for gas hob / cooker point | C27: P-103 … P-108 (Floor plans) | D27: Nr | E27: 15 | G27: =IF(OR(E27="",F27=""),"",E27*F27) | H27: 📋 MK / Schneider / Legrand / Hager
A28: Sub-Total 7.3 — 1F | G28: =SUM(G20:G28)
A30: 7.4 — 2F — SOCKET OUTLETS & SMALL POWER
A31: 7.4.1 | B31: 13A 230V SP switched socket outlet (BS 1363) | C31: P-103 … P-108 (Floor plans) | D31: Nr | E31: 88 | F31: 45 | G31: =IF(OR(E31="",F31=""),"",E31*F31) | H31: 📋 MK / Schneider / Legrand / Hager
A32: 7.4.2 | B32: 13A 230V twin switched socket outlet (BS 1363) | C32: P-103 … P-108 (Floor plans) | D32: Nr | E32: 162 | G32: =IF(OR(E32="",F32=""),"",E32*F32) | H32: 📋 MK / Schneider / Legrand / Hager
A33: 7.4.3 | B33: 13A 230V twin switched socket outlet + USB-A/USB-C ports | C33: P-103 … P-108 (Floor plans) | D33: Nr | E33: 30 | F33: 180 | G33: =IF(OR(E33="",F33=""),"",E33*F33) | H33: 📋 MK / Schneider / Legrand / Hager
A34: 7.4.4 | B34: 13A 230V weatherproof IP55 socket outlet | C34: P-103 … P-108 (Floor plans) | D34: Nr | E34: 30 | F34: 95 | G34: =IF(OR(E34="",F34=""),"",E34*F34) | H34: 📋 MK / Schneider / Legrand / Hager
A35: 7.4.5 | B35: 20A 230V flex outlet for water heater (with neon) | C35: P-103 … P-108 (Floor plans) | D35: Nr | E35: 22 | G35: =IF(OR(E35="",F35=""),"",E35*F35) | H35: 📋 MK / Schneider / Legrand / Hager
A36: 7.4.6 | B36: 20A 230V DP switch — water heater / cooker isolation | C36: P-103 … P-108 (Floor plans) | D36: Nr | E36: 30 | F36: 85 | G36: =IF(OR(E36="",F36=""),"",E36*F36) | H36: 📋 MK / Schneider / Legrand / Hager
A37: 7.4.7 | B37: 13A switched fused spur with neon for FCU (AC indoor unit) | C37: P-103 … P-108 (Floor plans) | D37: Nr | E37: 48 | F37: 45 | G37: =IF(OR(E37="",F37=""),"",E37*F37) | H37: 📋 MK / Schneider / Legrand / Hager
A38: 7.4.8 | B38: 13A flex outlet for gas hob / cooker point | C38: P-103 … P-108 (Floor plans) | D38: Nr | E38: 15 | G38: =IF(OR(E38="",F38=""),"",E38*F38) | H38: 📋 MK / Schneider / Legrand / Hager
A39: Sub-Total 7.4 — 2F | G39: =SUM(G31:G39)
A41: 7.5 — 3F — SOCKET OUTLETS & SMALL POWER
A42: 7.5.1 | B42: 13A 230V SP switched socket outlet (BS 1363) | C42: P-103 … P-108 (Floor plans) | D42: Nr | E42: 88 | F42: 45 | G42: =IF(OR(E42="",F42=""),"",E42*F42) | H42: 📋 MK / Schneider / Legrand / Hager
A43: 7.5.2 | B43: 13A 230V twin switched socket outlet (BS 1363) | C43: P-103 … P-108 (Floor plans) | D43: Nr | E43: 162 | G43: =IF(OR(E43="",F43=""),"",E43*F43) | H43: 📋 MK / Schneider / Legrand / Hager
A44: 7.5.3 | B44: 13A 230V twin switched socket outlet + USB-A/USB-C ports | C44: P-103 … P-108 (Floor plans) | D44: Nr | E44: 30 | F44: 180 | G44: =IF(OR(E44="",F44=""),"",E44*F44) | H44: 📋 MK / Schneider / Legrand / Hager
...

Sheet Bill 8 - Lighting Fixtures
A1: BILL No. 8 — LIGHTING FIXTURES (INTERNAL + EXTERNAL)
