Workbook

Sheet Cover
B2: BILL OF QUANTITIES
B4: ELECTRICAL POWER DISTRIBUTION WORKS — DEWA AUTHORITY
B7: Project | C7: Proposed B+G+8+R Commercial & Residential Building
B8: Owner / Client | C8: Qutaiba Ameen Abdal Kija
B9: Plot No. | C9: 6731315 — Al Barsha South Third, Dubai, UAE
B10: Architect | C10: Engr. Samer Mahmoud Ajami (Reg. 105181)
B11: Structural | C11: Engr. Mohamad Maher Myaser Jabban (Reg. 101079)
B12: MEP Consultant | C12: Future Art Engineering Consultancy
B13: Authority | C13: DEWA (Dubai Electricity & Water Authority)
B15: TENDER DETAILS
B16: Job No. | C16: FA_P379 / CRs B/010/25
B17: Drawing Ref | C17: P-001 … P-300 (14 sheets, Power Layout)
B18: Drawing Date | C18: 16.01.2026
B19: BOQ Date | C19: 24/06/2026
B20: Addendum No. | C20: 0
B21: BOQ Status | C21: PRICED (INDICATIVE) — Dubai 2026 market rates · review before submission
B22: Currency | C22: AED (UAE Dirham)
B23: VAT Rate | C23: 5% (UAE Federal)
B25: CONTRACTOR DETAILS
B26: Contractor | C26: SABI Engineering & Contracting LLC
B27: Address | C27: Dubai, United Arab Emirates
B28: Phone | C28: +971 4 XXX XXXX
B29: Email | C29: estimation@sabi.ae
B30: TRN | C30: 100XXXXXXXXXXXXX
B32: BUILDING ELECTRICAL LOAD
B33: Total Connected Load (TCL) | C33: 2117.06
B34: Demand Factor | C34: 0.75427716
B35: Maximum Demand (MD) | C35: =ROUND(C33*C34,0) -> 1597
B37: LIST OF BILLS
B38: Bill | C38: Description | H38: Sheet
B39: 1 | C39: General Items / Preliminaries | H39: Bill 1
B40: 2 | C40: HV / LV Main Distribution (Transformer, MDB, Generator, ATS, Capacitors) | H40: Bill 2
B41: 3 | C41: Sub-Main Distribution Boards (SMDBs) | H41: Bill 3
B42: 4 | C42: Distribution Boards (DBs) & Consumer Units | H42: Bill 4
B43: 5 | C43: LV Power Cables (Main + Distribution + Final Circuits) | H43: Bill 5
B44: 6 | C44: Cable Containment (Tray, Ladder, Trunking, Conduit) | H44: Bill 6
B45: 7 | C45: Wiring Devices & Accessories | H45: Bill 7
B46: 8 | C46: Lighting Fixtures (Internal + External) | H46: Bill 8
B47: 9 | C47: Earthing & Lightning Protection | H47: Bill 9
B48: 10 | C48: Emergency Lighting & Life Safety | H48: Bill 10
...

Sheet Preamble & Standards
B2: PREAMBLE & APPLICABLE STANDARDS
B4: 0. STATUTORY COMPLIANCE — UAE / DUBAI AUTHORITIES
B5: The works under this BOQ shall fully comply with the requirements of the following Dubai and UAE authorities. The contractor shall obtain all approvals, attend witnessed inspections, and submit all documentation required by each authority as part of the contract.
B6: Authority | C6: Scope of compliance
B7: DEWA | C7: Dubai Electricity & Water Authority — Distribution Standards, Service Connection Specifications, Smart Grid / Smart Metering programme, witnessed inspections, energising, meter sealing, As-Built filing.
B8: Dubai Municipality | C8: Building Code, Local Order 89/1994 (Building Regulations) and amendments, electrical safety inspections, occupancy / completion certificate clearance.
B9: DCD | C9: Dubai Civil Defence — UAE Fire & Life Safety Code of Practice (latest edition); fire-rated containment, FR/LSZH cable selection, emergency lighting, fire-fighter's lift, smoke-control fan power supplies.
B10: UAE Federal | C10: Federal Tax Authority — VAT (5%) per UAE VAT Law (Federal Decree-Law No. 8 of 2017); MoCCAE / ESMA conformity certificates for electrical equipment placed on UAE market.
B12: 1. SCOPE OF WORKS
B13: Supply, installation, testing and commissioning of the complete LV electrical distribution system, lighting, small power, earthing & lightning protection, metering and life-safety related electrical installations for the project, in accordance with the tender drawings, specifications, applicable standards, and authority requirements (DEWA, Dubai Municipality, Dubai Civil Defence). The scope shall include all materials, labour, plant, supervision, transport, scaffolding, builder's work in connection, testing instruments, commissioning, As-Built drawings and O&M manuals.
B15: 2. APPLICABLE STANDARDS
B16: Standard | C16: Description
B17: DEWA | C17: Distribution Standards & Authority Regulations (latest edition)
B18: DEWA Smart Grid | C18: Smart Metering Programme / AMI Specifications / Shams Dubai
B19: DM | C19: Dubai Municipality Building Code & Electrical Inspection Standards
B20: DM Local Order | C20: Local Order 89/1994 — Building Regulations and amendments
B21: DCD | C21: Dubai Civil Defence — UAE Fire & Life Safety Code of Practice (latest)
B22: BS 7671 | C22: IEE Wiring Regulations (18th Edition / latest)
B23: IEC 60364 | C23: Low-voltage electrical installations
B24: IEC 60439 | C24: LV switchgear and controlgear assemblies (Form separation)
B25: IEC 60947 | C25: LV switchgear (ACBs, MCCBs, contactors)
B26: IEC 60331 | C26: Fire-resisting characteristics of electric cables
B27: BS 6387 CWZ | C27: Performance requirements for fire-rated cables
... B35: UAE FTA | C35: Federal Tax Authority — VAT (5%) on tender total per Federal Decree-Law 8/2017
B37: 3. ABBREVIATIONS
B38: Abbr. | C38: Meaning
B39: ACB | C39: Air Circuit Breaker
B40: MCCB | C40: Moulded Case Circuit Breaker
B41: MCB | C41: Miniature Circuit Breaker
B42: RCD | C42: Residual Current Device
B43: LVP | C43: LV Panel (Main)
B44: SMDB | C44: Sub-Main Distribution Board
B45: ESMDB | C45: Emergency SMDB
B46: DB | C46: Distribution Board
B47: EDB | C47: Emergency DB
B48: ATS | C48: Automatic Transfer Switch
B49: XLPE | C49: Cross-Linked Polyethylene
... B64: IP55/IP65 | C64: Ingress Protection ratings
B67: 4. PRICING NOTES
B68: (1) | C68: All rates shall include supply, delivery, off-loading, storage, installation, fixings, support steelwork, painting, identification labelling, testing, commissioning, and handover.
...

Sheet Bill 1 - Preliminaries
A1: BILL No. 1 — GENERAL ITEMS / PRELIMINARIES
A2: Project: Proposed B+G+8+R Commercial & Residential Building, Plot 6731315, Al Barsha South Third, Dubai, UAE | Job: FA_P379 / CRs B/010/25 | Authority: DEWA (Dubai Electricity & Water Authority)
A3: Item | B3: Description | C3: Reference | D3: Unit | E3: Qty | F3: Rate (AED) | G3: Amount (AED) | H3: Origin / Brand
A4: 1.1 — PROJECT MOBILISATION & SITE ESTABLISHMENT
A5: 1.1.1 | B5: Mobilisation to site, including transport of plant, tools, materials and personnel. | C5: — | D5: Sum | E5: 1 | F5: 125000 | G5: =IF(OR(E5="",F5=""),"",E5*F5) | H5: 📋 — (contractor selection)
A6: 1.1.2 | B6: Site offices, storage compounds, sanitary and welfare facilities for the duration of the works. | C6: — | D6: Sum | E6: 1 | F6: 85000 | G6: =IF(OR(E6="",F6=""),"",E6*F6) | H6: 📋 — (contractor selection)
A7: 1.1.3 | B7: Site hoarding, fencing and security as per main contractor / consultant requirements. | C7: — | D7: Sum | E7: 1 | F7: 35000 | G7: =IF(OR(E7="",F7=""),"",E7*F7) | H7: 📋 — (contractor selection)
A8: 1.1.4 | B8: Health & Safety plan, PPE, fall-arrest and electrical safety (LOTO) provisions for the duration. | C8: — | D8: Sum | E8: 1 | F8: 18000 | G8: =IF(OR(E8="",F8=""),"",E8*F8) | H8: 📋 — (contractor selection)
A9: 1.1.5 | B9: Coordination with main contractor and other MEP trades — shop-drawing review meetings, BIM coordination as required. | C9: — | D9: Sum | E9: 1 | F9: 25000 | G9: =IF(OR(E9="",F9=""),"",E9*F9) | H9: 📋 — (contractor selection)
A10: Sub-Total 1.1 | G10: =SUM(G5:G9)
A12: 1.2 — INSURANCE & BONDS
A13: 1.2.1 | B13: Contractor's All Risks (CAR) insurance for the contract value, full duration plus DLP. | C13: — | D13: Sum | E13: 1 | F13: 85000 | G13: =IF(OR(E13="",F13=""),"",E13*F13) | H13: 📋 — (contractor selection)
A14: 1.2.2 | B14: Workmen's Compensation and Public Liability insurance. | C14: — | D14: Sum | E14: 1 | F14: 45000 | G14: =IF(OR(E14="",F14=""),"",E14*F14) | H14: 📋 — (contractor selection)
A15: 1.2.3 | B15: Performance bond (10% of contract value) — bank guarantee in favour of the employer. | C15: — | D15: Sum | E15: 1 | F15: 18000 | G15: =IF(OR(E15="",F15=""),"",E15*F15) | H15: 📋 — (contractor selection)
A16: 1.2.4 | B16: Advance payment guarantee — bank guarantee against advance. | C16: — | D16: Sum | E16: 1 | F16: 12000 | G16: =IF(OR(E16="",F16=""),"",E16*F16) | H16: 📋 — (contractor selection)
A17: Sub-Total 1.2 | G17: =SUM(G13:G16)
A19: 1.3 — TEMPORARY UTILITIES & TESTING INSTRUMENTS
A20: 1.3.1 | B20: Temporary power supply during construction — generator, distribution, metering, fuel. | C20: — | D20: Sum | E20: 1 | F20: 85000 | G20: =IF(OR(E20="",F20=""),"",E20*F20) | H20: 📋 — (contractor selection)
A21: 1.3.2 | B21: Temporary lighting in areas of work as required for safe execution. | C21: — | D21: Sum | E21: 1 | F21: 25000 | G21: =IF(OR(E21="",F21=""),"",E21*F21) | H21: 📋 — (contractor selection)
A22: 1.3.3 | B22: Provision of all testing instruments — Megger 500V/1000V, earth tester, multimeter, RCD tester, loop tester, calibration certificates current. | C22: — | D22: Sum | E22: 1 | F22: 5500 | G22: =IF(OR(E22="",F22=""),"",E22*F22) | H22: 📋 — (contractor selection)
A23: Sub-Total 1.3 | G23: =SUM(G20:G22)
A25: 1.4 — SUBMITTALS, AS-BUILTS, O&M MANUALS
A26: 1.4.1 | B26: Shop drawings (AutoCAD) — full set, multiple revisions until approved. | C26: — | D26: Sum | E26: 1 | F26: 85000 | G26: =IF(OR(E26="",F26=""),"",E26*F26) | H26: 📋 — (contractor selection)
A27: 1.4.2 | B27: Material approval submittals — datasheets, samples, manufacturer's certificates, country-of-origin declarations. | C27: — | D27: Sum | E27: 1 | F27: 35000 | G27: =IF(OR(E27="",F27=""),"",E27*F27) | H27: 📋 — (contractor selection)
A28: 1.4.3 | B28: As-Built drawings (AutoCAD + PDF, 4 hard copies) at handover. | C28: — | D28: Sum | E28: 1 | F28: 45000 | G28: =IF(OR(E28="",F28=""),"",E28*F28) | H28: 📋 — (contractor selection)
A29: 1.4.4 | B29: Operation & Maintenance manuals (4 hard copies + PDF) at handover, including spare-parts list. | C29: — | D29: Sum | E29: 1 | F29: 38000 | G29: =IF(OR(E29="",F29=""),"",E29*F29) | H29: 📋 — (contractor selection)
A30: 1.4.5 | B30: Defects Liability Period support (12 months from handover) — site attendance, replacement of defective materials, retesting. | C30: — | D30: Sum | E30: 1 | F30: 12000 | G30: =IF(OR(E30="",F30=""),"",E30*F30) | H30: 📋 — (contractor selection)
A31: Sub-Total 1.4 | G31: =SUM(G26:G30)
A33: 1.5 — AUTHORITY FEES, NOCs & PERMITS
A34: 1.5.1 | B34: DEWA HV/LV connection capacity charges (per kVA, DEWA tariff). Provisional sum — final amount per DEWA load-letter response. | C34: DEWA / DM / DCD / RTA tariff | D34: Sum | E34: 1 | F34: 350000 | G34: =IF(OR(E34="",F34=""),"",E34*F34) | H34: 📋 DEWA / DM / DCD / RTA
A35: 1.5.2 | B35: DEWA load-letter application & approval fees (capacity allocation, RMU/substation siting, voltage level confirmation). | C35: DEWA / DM / DCD / RTA tariff | D35: Sum | E35: 1 | F35: 8000 | G35: =IF(OR(E35="",F35=""),"",E35*F35) | H35: 📋 DEWA / DM / DCD / RTA
A36: 1.5.3 | B36: DEWA energising application fee — submission, processing, witness arrangement, meter sealing. | C36: DEWA / DM / DCD / RTA tariff | D36: Sum | E36: 1 | F36: 12000 | G36: =IF(OR(E36="",F36=""),"",E36*F36) | H36: 📋 DEWA / DM / DCD / RTA
A37: 1.5.4 | B37: RTA road-cutting permit + reinstatement (where HV/LV cabling crosses public road or pavement). Provisional sum. | C37: DEWA / DM / DCD / RTA tariff | D37: Sum | E37: 1 | F37: 45000 | G37: =IF(OR(E37="",F37=""),"",E37*F37) | H37: 📋 DEWA / DM / DCD / RTA
A38: 1.5.5 | B38: Dubai Municipality (DM) electrical inspection & completion-certificate fee — for occupancy / completion sign-off. | C38: DEWA / DM / DCD / RTA tariff | D38: Sum | E38: 1 | F38: 18000 | G38: =IF(OR(E38="",F38=""),"",E38*F38) | H38: 📋 DEWA / DM / DCD / RTA
A39: 1.5.6 | B39: Dubai Civil Defence (DCD) electrical clearance NOC fee — life-safety clearance for fire pump, smoke control, emergency lighting. | C39: DEWA / DM / DCD / RTA tariff | D39: Sum | E39: 1 | F39: 12000 | G39: =IF(OR(E39="",F39=""),"",E39*F39) | H39: 📋 DEWA / DM / DCD / RTA
A40: Sub-Total 1.5 | G40: =SUM(G34:G39)
A43: BILL 1 — TOTAL CARRIED TO SUMMARY | G43: =SUMIF(A4:A41,"*.*.*",G4:G41)

Sheet Bill 2 - HV-LV Main
A1: BILL No. 2 — HV / LV MAIN DISTRIBUTION
A2: Project: Proposed B+G+8+R Commercial & Residential Building, Plot 6731315, Al Barsha South Third, Dubai, UAE | Job: FA_P379 / CRs B/010/25 | Authority: DEWA (Dubai Electricity & Water Authority)
A3: Item | B3: Description | C3: Reference | D3: Unit | E3: Qty | F3: Rate (AED) | G3: Amount (AED) | H3: Origin / Brand
A4: 2.1 — HV INCOMING SUPPLY & TRANSFORMER (DEWA-coordinated)
A5: 2.1.1 | B5: DEWA HV incoming service connection (RMU / package substation, supplied & installed by DEWA). Contractor allowance for coordination, application, attendance and acceptance. | C5: P-200 (SLD) / P-300 (LV room) | D5: Lot | E5: 1 | F5: 0 | G5: =IF(OR(E5="",F5=""),"",E5*F5) | H5: 📋 DEWA-listed
A6: 2.1.2 | B6: HV / LV distribution transformer — 1000 kVA, 11kV/400V, 50 Hz, vector group Dyn11, K-Factor rating ≥ K-13 (suitable for non-linear loads — LED lighting, EV chargers, VFDs; uplift to K-20 if EV load > 20 % of MD), cast-resin (dry-type) construction with encapsulated F-class windings, IP31 enclosure, anti-vibration mounts, ±2.5 % / ±5 % off-circuit tap changer, oil-free, low-loss DEWA-listed manufacturer. Per DEWA-coordinated supply (transformer by DEWA — supply line for record / contractor coordination). Includes installation, energising, witnessed routine test, commissioning report. | C6: P-200 (SLD) / P-300 (LV room) | D6: Nr | E6: 1 | F6: 120000 | G6: =IF(OR(E6="",F6=""),"",E6*F6) | H6: 📋 Schneider / ABB / Siemens / Trafo Union
A7: 2.1.3 | B7: HV / LV distribution transformer — 1500 kVA, 11kV/400V, 50 Hz, vector group Dyn11, K-Factor rating ≥ K-13 (suitable for non-linear loads — LED lighting, EV chargers, VFDs; uplift to K-20 if EV load > 20 % of MD), cast-resin (dry-type) construction with encapsulated F-class windings, IP31 enclosure, anti-vibration mounts, ±2.5 % / ±5 % off-circuit tap changer, oil-free, low-loss DEWA-listed manufacturer. Per DEWA-coordinated supply (transformer by DEWA — supply line for record / contractor coordination). Includes installation, energising, witnessed routine test, commissioning report. | C7: P-200 (SLD) / P-300 (LV room) | D7: Nr | E7: 1 | F7: 180000 | G7: =IF(OR(E7="",F7=""),"",E7*F7) | H7: 📋 Schneider / ABB / Siemens / Trafo Union
A8: 2.1.4 | B8: 11 kV HV cable (single-core 3×1C, XLPE/CWS/PVC, copper screen) from RMU to transformer HV side — complete with stress cones, heat-shrink terminations, fire stopping at penetrations, earthing, ID phase markers. | C8: P-200 (SLD) / P-300 (LV room) | D8: m | E8: 30 | F8: 18000 | G8: =IF(OR(E8="",F8=""),"",E8*F8) | H8: 📋 — (contractor selection)
A9: 2.1.5 | B9: Transformer room civil / MEP coordination — pressure-relief vents, mechanical ventilation, drainage, fire-rated enclosure (≥ 2 h), DEWA-spec oil bund where oil-filled (N/A for cast-resin) — coordination only. | C9: P-200 (SLD) / P-300 (LV room) | D9: Sum | E9: 1 | F9: 35000 | G9: =IF(OR(E9="",F9=""),"",E9*F9) | H9: 📋 Schneider / ABB / Siemens / Trafo Union
A10: Sub-Total 2.1 | G10: =SUM(G5:G9)
A12: 2.2 — LV PANELS (Supply, Install, Test & Commission)
A13: 2.2.1 | B13: LVP-01: Type-tested LV switchboard (TTA / IEC 61439-1/2), 3P+N+E, 415 V, 50 Hz, floor-standing metal-clad, IP41 (front) / IP31 (rear), Form 4b separation, electro-tin-plated copper busbars rated 2500 A continuous with 50 kA Icw 1 s short-time withstand. Includes 2000A 4P main ACB drawout type, Icu ≥ 50 kA, Ics = 100 % Icu, electronic LSIG trip unit, neutral earthing link, surge protection device (SPD Type 1+2 at incomer), digital MFM metering with MODBUS RTU/TCP, voltage / current / phase indication, panel internal lighting, anti-condensation heater. Outgoing: 8× 300A TP→SMDB-1F..8F. Manufacturer's witnessed factory acceptance test (FAT) certificate. Complete installed, energised, with witnessed routine test certificate. | C13: P-200 (SLD) / P-300 (LV room) | D13: Nr | E13: 1 | F13: 600000 | G13: =IF(OR(E13="",F13=""),"",E13*F13) | H13: 📐 Schneider / ABB / Siemens / Eaton
A14: 2.2.2 | B14: Automatic PF correction capacitor bank — 375 kVAR, 415V, multi-step (typically 25/50 kVAR steps), with PF controller, contactors, detuning reactors (5.7%), incomer ACB, ID-labelled. For LVP-01. | C14: P-200 (SLD) / P-300 (LV room) | D14: Nr | E14: 1 | F14: 78750 | G14: =IF(OR(E14="",F14=""),"",E14*F14) | H14: 📐 ABB / Schneider / Cirprotec / Frako
A15: 2.2.3 | B15: LVP-02: Type-tested LV switchboard (TTA / IEC 61439-1/2), 3P+N+E, 415 V, 50 Hz, floor-standing metal-clad, IP41 (front) / IP31 (rear), Form 4b separation, electro-tin-plated copper busbars rated 2000 A continuous with 50 kA Icw 1 s short-time withstand. Includes 1600A 4P main ACB drawout type, Icu ≥ 50 kA, Ics = 100 % Icu, electronic LSIG trip unit, neutral earthing link, surge protection device (SPD Type 1+2 at incomer), digital MFM metering with MODBUS RTU/TCP, voltage / current / phase indication, panel internal lighting, anti-condensation heater. Outgoing: 1× 500A TP→SMDB-RF, 1× 160A TP→SMDB-EV, 1× 125A TP→SMDB-G, 12× 50A TP→SMDB-SH01..12, 1× 400A TP→ESMDB-G, 1× 350A TP→Fire Pump. Manufacturer's witnessed factory acceptance test (FAT) certificate. Complete installed, energised, with witnessed routine test certificate. | C15: P-200 (SLD) / P-300 (LV room) | D15: Nr | E15: 1 | F15: 450000 | G15: =IF(OR(E15="",F15=""),"",E15*F15) | H15: 📐 Schneider / ABB / Siemens / Eaton
A16: 2.2.4 | B16: Automatic PF correction capacitor bank — 275 kVAR, 415V, multi-step (typically 25/50 kVAR steps), with PF controller, contactors, detuning reactors (5.7%), incomer ACB, ID-labelled. For LVP-02. | C16: P-200 (SLD) / P-300 (LV room) | D16: Nr | E16: 1 | F16: 57750 | G16: =IF(OR(E16="",F16=""),"",E16*F16) | H16: 📐 ABB / Schneider / Cirprotec / Frako
A17: Sub-Total 2.2 | G17: =SUM(G13:G16)
A19: 2.3 — STANDBY GENERATOR & ATS
A20: 2.3.1 | B20: Standby Generator — 300 kVA, 415V/3Ph/50Hz, diesel-engined, weatherproof acoustic canopy ≤75 dB(A) @1m, AMF panel, fuel tank (8h running), exhaust system with silencer, anti-vibration mounts, day-tank, fuel transfer pump, control wiring. Complete installed, commissioned, with full-load test certificate. | C20: P-200 (SLD) / P-300 (LV room) | D20: Nr | E20: 1 | F20: 255000 | G20: =IF(OR(E20="",F20=""),"",E20*F20) | H20: 📐 Cummins / Caterpillar / FG Wilson / Perkins
A21: 2.3.2 | B21: Automatic Transfer Switch (ATS) Panel — 415V, 400A, 4P, with mechanical/electrical interlock, programmable controller, mains/gen voltage and frequency monitoring, soak-back & cool-down timers. Complete with controls, power and signalling cables. | C21: P-200 (SLD) / P-300 (LV room) | D21: Nr | E21: 1 | F21: 80000 | G21: =IF(OR(E21="",F21=""),"",E21*F21) | H21: 📐 ABB / Socomec / Cummins / GE
A22: Sub-Total 2.3 | G22: =SUM(G20:G21)
A25: BILL 2 — TOTAL CARRIED TO SUMMARY | G25: =SUMIF(A4:A23,"*.*.*",G4:G23)

Sheet Bill 3 - SMDBs
A1: BILL No. 3 — SUB-MAIN DISTRIBUTION BOARDS (SMDBS)
A2: Project: Proposed B+G+8+R Commercial & Residential Building, Plot 6731315, Al Barsha South Third, Dubai, UAE | Job: FA_P379 / CRs B/010/25 | Authority: DEWA (Dubai Electricity & Water Authority)
A3: Item | B3: Description | C3: Reference | D3: Unit | E3: Qty | F3: Rate (AED) | G3: Amount (AED) | H3: Origin / Brand
A4: 3 — SMDBs (no take-off data — populate from SLD)
A6: BILL 3 — TOTAL CARRIED TO SUMMARY | G6: =SUMIF(A4:A4,"*.*.*",G4:G4)

Sheet Bill 4 - Distribution Boards
A1: BILL No. 4 — DISTRIBUTION BOARDS (DBS) & CONSUMER UNITS
A2: Project: Proposed B+G+8+R Commercial & Residential Building, Plot 6731315, Al Barsha South Third, Dubai, UAE | Job: FA_P379 / CRs B/010/25 | Authority: DEWA (Dubai Electricity & Water Authority)
A3: Item | B3: Description | C3: Reference | D3: Unit | E3: Qty | F3: Rate (AED) | G3: Amount (AED) | H3: Origin / Brand
A4: 4 — Distribution Boards (no take-off data)
A5: 4.2 — MECHANICAL & SERVICE EQUIPMENT — POWER CONNECTIONS
A6: 4.2.1 | B6: Power supply & final connection to FAHU (Fresh Air Handling Unit) (174.66 kW) — incl. local weatherproof isolator / control switch, glanding, termination & connection to equipment terminals, and control / interlock wiring where shown. Feeder cable & upstream DB/MCCB measured separately (Bills 5 & 3/4.1). Test & commission jointly with the mechanical contractor. | C6: P-106 (Roof) / P-201 (SLD) | D6: Nr | E6: 1 | F6: 3200 | G6: =IF(OR(E6="",F6=""),"",E6*F6) | H6: 📐 Schneider / Hager / Legrand / ABB
A7: 4.2.2 | B7: Power supply & final connection to Fire pump (jockey + main + diesel cooling) (98 kW) — incl. local weatherproof isolator / control switch, glanding, termination & connection to equipment terminals, and control / interlock wiring where shown. Feeder cable & upstream DB/MCCB measured separately (Bills 5 & 3/4.1). Test & commission jointly with the mechanical contractor. | C7: P-106 (Roof) / P-201 (SLD) | D7: Nr | E7: 1 | F7: 3200 | G7: =IF(OR(E7="",F7=""),"",E7*F7) | H7: 📐 Schneider / Hager / Legrand / ABB
A8: 4.2.3 | B8: Power supply & final connection to EV chargers (7 kW + 22 kW points) (88 kW) — incl. local weatherproof isolator / control switch, glanding, termination & connection to equipment terminals, and control / interlock wiring where shown. Feeder cable & upstream DB/MCCB measured separately (Bills 5 & 3/4.1). Test & commission jointly with the mechanical contractor. | C8: P-106 (Roof) / P-201 (SLD) | D8: Nr | E8: 10 | F8: 3200 | G8: =IF(OR(E8="",F8=""),"",E8*F8) | H8: 📐 Schneider / Hager / Legrand / ABB
A9: Sub-Total 4.2 | G9: =SUM(G6:G8)
A12: BILL 4 — TOTAL CARRIED TO SUMMARY | G12: =SUMIF(A4:A10,"*.*.*",G4:G10)

Sheet Bill 5 - LV Cables
A1: BILL No. 5 — LV POWER CABLES (MAIN + DISTRIBUTION + FINAL CIRCUITS)
A2: Project: Proposed B+G+8+R Commercial & Residential Building, Plot 6731315, Al Barsha South Third, Dubai, UAE | Job: FA_P379 / CRs B/010/25 | Authority: DEWA (Dubai Electricity & Water Authority)
A3: Item | B3: Description | C3: Reference | D3: Unit | E3: Qty | F3: Rate (AED) | G3: Amount (AED) | H3: Origin / Brand
A4: 5.5 — LSZH CABLES — Public-Area & Escape-Route Final Circuits (DCD compliance)
A5: 5.5.1 | B5: LSZH XLPE/SWA/LSZH 4C × 16 mm² 600/1000 V cable to BS 7211 / IEC 60332-3 Cat C / IEC 61034 (low smoke) / IEC 60754 (zero halogen) — corridor & lobby final-circuit risers, escape-route mains. | C5: P-103 … P-108 / P-201 | D5: m | E5: 220 | F5: 42 | G5: =IF(OR(E5="",F5=""),"",E5*F5) | H5: 📋 Ducab LSZH / Prysmian / Helkama / Nexans
A6: 5.5.2 | B6: LSZH XLPE/LSZH 3C × 4 mm² Cu cable — apartment lighting & socket sub-mains in escape corridors. | C6: P-103 … P-108 / P-201 | D6: m | E6: 480 | F6: 11 | G6: =IF(OR(E6="",F6=""),"",E6*F6) | H6: 📋 Ducab LSZH / Prysmian / Helkama / Nexans
A7: 5.5.3 | B7: LSZH XLPE/LSZH 3C × 2.5 mm² Cu cable — final-circuit drops to apartment outlets & accessories on escape route. | C7: P-103 … P-108 / P-201 | D7: m | E7: 1200 | F7: 8 | G7: =IF(OR(E7="",F7=""),"",E7*F7) | H7: 📋 Ducab LSZH / Prysmian / Helkama / Nexans
A8: 5.5.4 | B8: LSZH XLPE/LSZH 2C × 1.5 mm² Cu cable — emergency / exit-sign final circuits (combined with FR per Bill 5.2). | C8: P-103 … P-108 / P-201 | D8: m | E8: 540 | F8: 7 | G8: =IF(OR(E8="",F8=""),"",E8*F8) | H8: 📋 Ducab FR / Pirelli / Prysmian / Nexans
A9: Sub-Total 5.5 | G9: =SUM(G5:G8)
A12: BILL 5 — TOTAL CARRIED TO SUMMARY | G12: =SUMIF(A4:A10,"*.*.*",G4:G10)

Sheet Bill 6 - Containment
A1: BILL No. 6 — CABLE CONTAINMENT (TRAY, LADDER, TRUNKING, CONDUIT)
A2: Project: Proposed B+G+8+R Commercial & Residential Building, Plot 6731315, Al Barsha South Third, Dubai, UAE | Job: FA_P379 / CRs B/010/25 | Authority: DEWA (Dubai Electricity & Water Authority)
A3: Item | B3: Description | C3: Reference | D3: Unit | E3: Qty | F3: Rate (AED) | G3: Amount (AED) | H3: Origin / Brand
A4: 6.1 — CABLE TRAYS, LADDERS, TRUNKING & CONDUITS
A5: 6.1.1 | B5: GI hot-dip galvanised cable ladder, 500mm wide × 100mm side rail (vertical riser shaft, UG to Roof), hot-dip galvanised to BS EN ISO 1461, c/w supports at max 1.5m centres on horizontal / 1.0m on vertical, brackets, bends, tees, reducers, copplers, fixings, earth bonding straps. | C5: P-010 (Cable tray detail) / P-201 | D5: m | E5: 40 | F5: 640 | G5: =IF(OR(E5="",F5=""),"",E5*F5) | H5: 📋 Marshall Tufflex / Vergokan / Niedax / Eltete
A6: 6.1.2 | B6: GI hot-dip galvanised cable ladder, 300mm wide × 100mm side rail (horizontal at each floor riser→SMDB), hot-dip galvanised to BS EN ISO 1461, c/w supports at max 1.5m centres on horizontal / 1.0m on vertical, brackets, bends, tees, reducers, copplers, fixings, earth bonding straps. | C6: P-010 (Cable tray detail) / P-201 | D6: m | E6: 130 | F6: 385 | G6: =IF(OR(E6="",F6=""),"",E6*F6) | H6: 📋 Marshall Tufflex / Vergokan / Niedax / Eltete
A7: 6.1.3 | B7: GI perforated cable tray, 200mm wide × 50mm deep (corridor distribution 1F–8F), hot-dip galvanised to BS EN ISO 1461, c/w supports at max 1.5m centres on horizontal / 1.0m on vertical, brackets, bends, tees, reducers, copplers, fixings, earth bonding straps. | C7: P-010 (Cable tray detail) / P-201 | D7: m | E7: 400 | F7: 310 | G7: =IF(OR(E7="",F7=""),"",E7*F7) | H7: 📋 Marshall Tufflex / Vergokan / Niedax / Eltete
A8: 6.1.4 | B8: GI perforated cable tray, 100mm wide × 50mm deep (branch distribution to DBs), hot-dip galvanised to BS EN ISO 1461, c/w supports at max 1.5m centres on horizontal / 1.0m on vertical, brackets, bends, tees, reducers, copplers, fixings, earth bonding straps. | C8: P-010 (Cable tray detail) / P-201 | D8: m | E8: 300 | F8: 160 | G8: =IF(OR(E8="",F8=""),"",E8*F8) | H8: 📋 Marshall Tufflex / Vergokan / Niedax / Eltete
A9: 6.1.5 | B9: GI perforated cable tray, 200mm wide × 50mm deep (Ground floor retail/common), hot-dip galvanised to BS EN ISO 1461, c/w supports at max 1.5m centres on horizontal / 1.0m on vertical, brackets, bends, tees, reducers, copplers, fixings, earth bonding straps. | C9: P-010 (Cable tray detail) / P-201 | D9: m | E9: 100 | F9: 310 | G9: =IF(OR(E9="",F9=""),"",E9*F9) | H9: 📋 Marshall Tufflex / Vergokan / Niedax / Eltete
A10: 6.1.6 | B10: GI perforated cable tray, 300mm wide × 75mm deep (Roof mechanical), hot-dip galvanised to BS EN ISO 1461, c/w supports at max 1.5m centres on horizontal / 1.0m on vertical, brackets, bends, tees, reducers, copplers, fixings, earth bonding straps. | C10: P-010 (Cable tray detail) / P-201 | D10: m | E10: 80 | F10: 385 | G10: =IF(OR(E10="",F10=""),"",E10*F10) | H10: 📋 Marshall Tufflex / Vergokan / Niedax / Eltete
A11: 6.1.7 | B11: 25mm uPVC conduit c/w draw wire, saddles, junction boxes, hot-dip galvanised to BS EN ISO 1461, c/w supports at max 1.5m centres on horizontal / 1.0m on vertical, brackets, bends, tees, reducers, copplers, fixings, earth bonding straps. | C11: P-010 (Cable tray detail) / P-201 | D11: m | E11: 535 | F11: 48 | G11: =IF(OR(E11="",F11=""),"",E11*F11) | H11: 📋 Marshall Tufflex / Pemsa / Atkore / DSS
A12: 6.1.8 | B12: 32mm uPVC conduit (cable tray to SMDB at each floor), hot-dip galvanised to BS EN ISO 1461, c/w supports at max 1.5m centres on horizontal / 1.0m on vertical, brackets, bends, tees, reducers, copplers, fixings, earth bonding straps. | C12: P-010 (Cable tray detail) / P-201 | D12: m | E12: 80 | F12: 62 | G12: =IF(OR(E12="",F12=""),"",E12*F12) | H12: 📋 Marshall Tufflex / Vergokan / Niedax / Eltete
A13: 6.1.9 | B13: 20mm uPVC conduit (final-circuit drops to outlets), hot-dip galvanised to BS EN ISO 1461, c/w supports at max 1.5m centres on horizontal / 1.0m on vertical, brackets, bends, tees, reducers, copplers, fixings, earth bonding straps. | C13: P-010 (Cable tray detail) / P-201 | D13: m | E13: 400 | F13: 48 | G13: =IF(OR(E13="",F13=""),"",E13*F13) | H13: 📋 Marshall Tufflex / Pemsa / Atkore / DSS
A14: 6.1.10 | B14: 25mm GI rigid conduit — fire-rated for emergency cable routes (staircase wells, fire shafts), hot-dip galvanised to BS EN ISO 1461, c/w supports at max 1.5m centres on horizontal / 1.0m on vertical, brackets, bends, tees, reducers, copplers, fixings, earth bonding straps. | C14: P-010 (Cable tray detail) / P-201 | D14: m | E14: 200 | F14: 77 | G14: =IF(OR(E14="",F14=""),"",E14*F14) | H14: 📋 Marshall Tufflex / Pemsa / Atkore / DSS
A15: Sub-Total 6.1 | G15: =SUM(G5:G14)
A18: BILL 6 — TOTAL CARRIED TO SUMMARY | G18: =SUMIF(A4:A16,"*.*.*",G4:G16)

Sheet Bill 7 - Wiring Devices
A1: BILL No. 7 — WIRING DEVICES & ACCESSORIES
A2: Project: Proposed B+G+8+R Commercial & Residential Building, Plot 6731315, Al Barsha South Third, Dubai, UAE | Job: FA_P379 / CRs B/010/25 | Authority: DEWA (Dubai Electricity & Water Authority)
A3: Item | B3: Description | C3: Reference | D3: Unit | E3: Qty | F3: Rate (AED) | G3: Amount (AED) | H3: Origin / Brand
A4: 7.1 — SOCKET OUTLETS
A5: 7.1.1 | B5: 13 A SP switched socket outlet (BS 1363), white moulded grid plate | C5: P-103 … P-108 (Floor plans) | D5: Nr | E5: 340 | F5: 45 | G5: =IF(OR(E5="",F5=""),"",E5*F5) | H5: 📋 MK / Schneider / Legrand / Hager
A6: 7.1.2 | B6: 13 A DP twin switched socket outlet (BS 1363) | C6: P-103 … P-108 (Floor plans) | D6: Nr | E6: 280 | F6: 75 | G6: =IF(OR(E6="",F6=""),"",E6*F6) | H6: 📋 MK / Schneider / Legrand / Hager
A7: 7.1.3 | B7: 20 A DP switched outlet for AC indoor unit | C7: P-103 … P-108 (Floor plans) | D7: Nr | E7: 95 | F7: 85 | G7: =IF(OR(E7="",F7=""),"",E7*F7) | H7: 📋 MK / Schneider / Legrand / Hager
A8: 7.1.4 | B8: 20 A DP switched outlet for water heater (with neon) | C8: P-103 … P-108 (Floor plans) | D8: Nr | E8: 50 | F8: 85 | G8: =IF(OR(E8="",F8=""),"",E8*F8) | H8: 📋 MK / Schneider / Legrand / Hager
A9: 7.1.5 | B9: 32 A cooker outlet with isolator + neon | C9: P-103 … P-108 (Floor plans) | D9: Nr | E9: 25 | F9: 165 | G9: =IF(OR(E9="",F9=""),"",E9*F9) | H9: 📋 MK / Schneider / Legrand / Hager
A10: 7.1.6 | B10: Floor-mounted service box (lobby / retail counters), 4-gang | C10: P-103 … P-108 (Floor plans) | D10: Nr | E10: 18 | F10: 280 | G10: =IF(OR(E10="",F10=""),"",E10*F10) | H10: 📋 MK / Schneider / Legrand / Hager
A11: 7.1.7 | B11: Shaver socket outlet (bathrooms) | C11: P-103 … P-108 (Floor plans) | D11: Nr | E11: 40 | F11: 95 | G11: =IF(OR(E11="",F11=""),"",E11*F11) | H11: 📋 MK / Schneider / Legrand / Hager
A12: Sub-Total 7.1 | G12: =SUM(G5:G11)
A14: 7.2 — SWITCHES & CONTROLS
A15: 7.2.1 | B15: 1-gang / 2-gang lighting switches, 10A 250V grid-style, white moulded plate (BS 3676) | C15: P-103 … P-108 (Floor plans) | D15: Nr | E15: 520 | F15: 25 | G15: =IF(OR(E15="",F15=""),"",E15*F15) | H15: 📋 MK / Schneider / Legrand / Hager
A16: 7.2.2 | B16: 2-way / intermediate switches (corridors, stairs) | C16: P-103 … P-108 (Floor plans) | D16: Nr | E16: 45 | F16: 30 | G16: =IF(OR(E16="",F16=""),"",E16*F16) | H16: 📋 MK / Schneider / Legrand / Hager
A17: 7.2.3 | B17: Dimmer switch, 1-gang, 250 W LED-compatible | C17: P-103 … P-108 (Floor plans) | D17: Nr | E17: 60 | F17: 120 | G17: =IF(OR(E17="",F17=""),"",E17*F17) | H17: 📋 MK / Schneider / Legrand / Hager
A18: 7.2.4 | B18: Occupancy / PIR sensor (corridors, BOH, stores), with manual override | C18: P-103 … P-108 (Floor plans) | D18: Nr | E18: 30 | F18: 95 | G18: =IF(OR(E18="",F18=""),"",E18*F18) | H18: 📋 MK / Schneider / Legrand / Hager
A19: 7.2.5 | B19: Doorbell push + chime kit (apartments) | C19: P-103 … P-108 (Floor plans) | D19: Set | E19: 25 | F19: 150 | G19: =IF(OR(E19="",F19=""),"",E19*F19) | H19: 📋 MK / Schneider / Legrand / Hager
A20: 7.2.6 | B20: Connection unit (FCU), 3 A fused, for ceiling/extract fans | C20: P-103 … P-108 (Floor plans) | D20: Nr | E20: 75 | F20: 60 | G20: =IF(OR(E20="",F20=""),"",E20*F20) | H20: 📋 MK / Schneider / Legrand / Hager
A21: Sub-Total 7.2 | G21: =SUM(G15:G20)
A23: 7.3 — ISOLATORS & EV CHARGER OUTLETS
A24: 7.3.1 | B24: Isolator, 4P 32A, weatherproof IP55, for outdoor mech. equipment | C24: P-103 … P-108 (Floor plans) | D24: Nr | E24: 22 | F24: 125 | G24: =IF(OR(E24="",F24=""),"",E24*F24) | H24: 📋 MK / Schneider / Legrand / Hager
A25: 7.3.2 | B25: Isolator, 2P 20A, indoor IP20 — small fixed equipment | C25: P-103 … P-108 (Floor plans) | D25: Nr | E25: 18 | F25: 75 | G25: =IF(OR(E25="",F25=""),"",E25*F25) | H25: 📋 MK / Schneider / Legrand / Hager
A26: 7.3.3 | B26: EV charger socket outlet — 7 kW AC Mode 3 Type 2 (basement parking) | C26: P-103 … P-108 (Floor plans) | D26: Nr | E26: 8 | F26: 3500 | G26: =IF(OR(E26="",F26=""),"",E26*F26) | H26: 📋 ABB Terra / Schneider / Wallbox / Delta
A27: 7.3.4 | B27: EV charger socket outlet — 22 kW AC Mode 3 Type 2 (basement parking) | C27: P-103 … P-108 (Floor plans) | D27: Nr | E27: 2 | F27: 8500 | G27: =IF(OR(E27="",F27=""),"",E27*F27) | H27: 📋 ABB Terra / Schneider / Wallbox / Delta
A28: Sub-Total 7.3 | G28: =SUM(G24:G27)
A31: BILL 7 — TOTAL CARRIED TO SUMMARY | G31: =SUMIF(A4:A29,"*.*.*",G4:G29)

Sheet Bill 8 - Lighting Fixtures
A1: BILL No. 8 — LIGHTING FIXTURES (INTERNAL + EXTERNAL)
A2: Project: Proposed B+G+8+R Commercial & Residential Building, Plot 6731315, Al Barsha South Third, Dubai, UAE | Job: FA_P379 / CRs B/010/25 | Authority: DEWA (Dubai Electricity & Water Authority)
A3: Item | B3: Description | C3: Reference | D3: Unit | E3: Qty | F3: Rate (AED) | G3: Amount (AED) | H3: Origin / Brand
A4: 8.1 — INTERIOR LIGHTING — APARTMENTS & COMMON AREAS
A5: 8.1.1 | B5: Recessed LED downlight, 12 W / 800 lm, 4000 K, IP20, anti-glare reflector (apartments, lobby, corridors) | C5: P-103 … P-108 (Floor plans) | D5: Nr | E5: 480 | F5: 85 | G5: =IF(OR(E5="",F5=""),"",E5*F5) | H5: 📋 Philips / Osram / Trilux / Thorn / Cooper
A6: 8.1.2 | B6: Surface-mount LED panel, 600×600 mm, 36 W / 3600 lm, 4000 K (lobby, BOH) | C6: P-103 … P-108 (Floor plans) | D6: Nr | E6: 60 | F6: 640 | G6: =IF(OR(E6="",F6=""),"",E6*F6) | H6: 📋 Philips / Osram / Trilux / Thorn / Cooper
A7: 8.1.3 | B7: Linear LED batten 1200 mm, 36 W / 4000 lm, 4000 K, IP40 (car park, services) | C7: P-103 … P-108 (Floor plans) | D7: Nr | E7: 220 | F7: 640 | G7: =IF(OR(E7="",F7=""),"",E7*F7) | H7: 📋 Philips / Osram / Trilux / Thorn / Cooper
A8: 8.1.4 | B8: Bulkhead LED fitting, 12 W, IP65, polycarbonate (staircase, plant rooms) | C8: P-103 … P-108 (Floor plans) | D8: Nr | E8: 90 | F8: 95 | G8: =IF(OR(E8="",F8=""),"",E8*F8) | H8: 📋 Philips / Osram / Trilux / Thorn / Cooper
A9: 8.1.5 | B9: Wall-mounted LED bracket light (corridors, accent) | C9: P-103 … P-108 (Floor plans) | D9: Nr | E9: 65 | F9: 150 | G9: =IF(OR(E9="",F9=""),"",E9*F9) | H9: 📋 Philips / Osram / Trilux / Thorn / Cooper
A10: 8.1.6 | B10: Pendant decorative LED fixture (lobby — provisional) | C10: P-103 … P-108 (Floor plans) | D10: Nr | E10: 8 | F10: 450 | G10: =IF(OR(E10="",F10=""),"",E10*F10) | H10: 📋 Philips / Osram / Trilux / Thorn / Cooper
A11: 8.1.7 | B11: Track lighting LED spot, 15 W, 3000 K (retail — provisional) | C11: P-103 … P-108 (Floor plans) | D11: Nr | E11: 40 | F11: 140 | G11: =IF(OR(E11="",F11=""),"",E11*F11) | H11: 📋 Philips / Osram / Trilux / Thorn / Cooper
A12: Sub-Total 8.1 | G12: =SUM(G5:G11)
A14: 8.2 — EXTERIOR LIGHTING (Façade, Podium, Parking)
A15: 8.2.1 | B15: External wall-mounted LED fixture, 24 W, IP65, anti-glare optic (podium, façade) | C15: P-100 (Site / external) | D15: Nr | E15: 36 | F15: 280 | G15: =IF(OR(E15="",F15=""),"",E15*F15) | H15: 📋 Philips Lumec / Disano / iGuzzini / Thorn
A16: 8.2.2 | B16: Pole-mounted parking LED area light, 80 W, 4000 K, IP66, on 6 m pole | C16: P-100 (Site / external) | D16: Nr | E16: 14 | F16: 1800 | G16: =IF(OR(E16="",F16=""),"",E16*F16) | H16: 📋 Philips Lumec / Disano / iGuzzini / Thorn
A17: 8.2.3 | B17: Step / kerb LED light, 3 W, IP67, recessed | C17: P-100 (Site / external) | D17: Nr | E17: 28 | F17: 95 | G17: =IF(OR(E17="",F17=""),"",E17*F17) | H17: 📋 Philips Lumec / Disano / iGuzzini / Thorn
A18: 8.2.4 | B18: Bollard LED, 20 W, IP65, 800 mm height (landscape) | C18: P-100 (Site / external) | D18: Nr | E18: 16 | F18: 640 | G18: =IF(OR(E18="",F18=""),"",E18*F18) | H18: 📋 Philips Lumec / Disano / iGuzzini / Thorn
A19: 8.2.5 | B19: Façade LED linear / wall-grazer, IP66 (provisional sum) | C19: P-100 (Site / external) | D19: Sum | E19: 1 | F19: 85000 | G19: =IF(OR(E19="",F19=""),"",E19*F19) | H19: 📋 Philips Lumec / Disano / iGuzzini / Thorn
A20: Sub-Total 8.2 | G20: =SUM(G15:G19)
A22: 8.3 — LIGHTING CONTROLS
A23: 8.3.1 | B23: Time-clock / astronomical timer for façade and external lighting | C23: P-200 (SLD) / Lighting controls | D23: Set | E23: 1 | F23: 85000 | G23: =IF(OR(E23="",F23=""),"",E23*F23) | H23: 📋 Philips Lumec / Disano / iGuzzini / Thorn
A24: 8.3.2 | B24: Photocell / daylight sensor for external circuits | C24: P-200 (SLD) / Lighting controls | D24: Nr | E24: 4 | F24: 250 | G24: =IF(OR(E24="",F24=""),"",E24*F24) | H24: 📋 MK / Schneider / Legrand / Hager
A25: 8.3.3 | B25: DALI/0-10V dimmer module for common-area lighting (provisional) | C25: P-200 (SLD) / Lighting controls | D25: Sum | E25: 1 | F25: 120 | G25: =IF(OR(E25="",F25=""),"",E25*F25) | H25: 📋 Philips / Osram / Trilux / Thorn / Cooper
A26: Sub-Total 8.3 | G26: =SUM(G23:G25)
A29: BILL 8 — TOTAL CARRIED TO SUMMARY | G29: =SUMIF(A4:A27,"*.*.*",G4:G27)

Sheet Bill 9 - Earthing & LP
A1: BILL No. 9 — EARTHING & LIGHTNING PROTECTION
A2: Project: Proposed B+G+8+R Commercial & Residential Building, Plot 6731315, Al Barsha South Third, Dubai, UAE | Job: FA_P379 / CRs B/010/25 | Authority: DEWA (Dubai Electricity & Water Authority)
A3: Item | B3: Description | C3: Reference | D3: Unit | E3: Qty | F3: Rate (AED) | G3: Amount (AED) | H3: Origin / Brand
A4: 9.1 — MAIN EARTHING SYSTEM (TN-S, ≤ 1 Ω)
A5: 9.1.1 | B5: Main earth bar (MEB) in LV room — 50×6mm copper busbar, drilled and labelled, c/w insulators and fixing | C5: P-300 (LV room) / P-001 (Notes) | D5: Nr | E5: 2 | F5: 14 | G5: =IF(OR(E5="",F5=""),"",E5*F5) | H5: 📋 Erico / Furse / DEHN / Pentair
A6: 9.1.2 | B6: Earth pit (BS 7430 / DEWA) — 1200mm copper-bonded steel earth rod, inspection chamber, backfill, conductor clamp. Test < 1 Ω | C6: P-300 (LV room) / P-001 (Notes) | D6: Nr | E6: 4 | F6: 640 | G6: =IF(OR(E6="",F6=""),"",E6*F6) | H6: 📋 Erico / Furse / DEHN / Pentair
A7: 9.1.3 | B7: 1C × 95mm² bare copper earth conductor — MEB to earth pits and DEWA earth terminal | C7: P-300 (LV room) / P-001 (Notes) | D7: m | E7: 30 | F7: 36 | G7: =IF(OR(E7="",F7=""),"",E7*F7) | H7: 📋 Erico / Furse / DEHN / Pentair
A8: 9.1.4 | B8: 1C × 50mm² green/yellow PVC earth conductor — MEB to structural steel bonding points, water/gas entry | C8: P-300 (LV room) / P-001 (Notes) | D8: m | E8: 40 | F8: 23 | G8: =IF(OR(E8="",F8=""),"",E8*F8) | H8: 📋 Erico / Furse / DEHN / Pentair
A9: 9.1.5 | B9: 1C × 35mm² green/yellow XLPE earth conductor — MEB to sub-earth bar at each SMDB | C9: P-300 (LV room) / P-001 (Notes) | D9: m | E9: 400 | F9: 17 | G9: =IF(OR(E9="",F9=""),"",E9*F9) | H9: 📋 Ducab / NCC / Oman Cables / Riyadh Cables
A10: 9.1.6 | B10: 1C × 10mm² green/yellow PVC earth conductor — SMDB earth bar to each DB on residential floors | C10: P-300 (LV room) / P-001 (Notes) | D10: m | E10: 600 | F10: 6 | G10: =IF(OR(E10="",F10=""),"",E10*F10) | H10: 📋 Erico / Furse / DEHN / Pentair
A11: 9.1.7 | B11: Supplementary bonding conductor 4mm² — pipework, trays, equipment frames (provisional) | C11: P-300 (LV room) / P-001 (Notes) | D11: Sum | E11: 1 | F11: 11 | G11: =IF(OR(E11="",F11=""),"",E11*F11) | H11: 📋 Erico / Furse / DEHN / Pentair
A12: Sub-Total 9.1 | G12: =SUM(G5:G11)
A14: 9.2 — LIGHTNING PROTECTION (IEC 62305)
A15: 9.2.1 | B15: Air termination — Franklin/ESE rod, copper-bonded, with insulator + fixing (rooftop) | C15: P-100 (Site) / P-108 (Roof) | D15: Nr | E15: 6 | F15: 1800 | G15: =IF(OR(E15="",F15=""),"",E15*F15) | H15: 📋 DEHN / Erico / Furse / Helita
A16: 9.2.2 | B16: Down conductor — 50mm² bare copper tape/wire, full building height (basement to roof) | C16: P-100 (Site) / P-108 (Roof) | D16: m | E16: 240 | F16: 85 | G16: =IF(OR(E16="",F16=""),"",E16*F16) | H16: 📋 DEHN / Erico / Furse / Helita
A17: 9.2.3 | B17: Test point chamber with disconnector, lockable lid, at base of each down conductor | C17: P-100 (Site) / P-108 (Roof) | D17: Nr | E17: 4 | F17: 1200 | G17: =IF(OR(E17="",F17=""),"",E17*F17) | H17: 📋 DEHN / Erico / Furse / Helita
A18: 9.2.4 | B18: Earth electrode for LP system — copper-bonded rod + inspection chamber | C18: P-100 (Site) / P-108 (Roof) | D18: Nr | E18: 4 | F18: 3500 | G18: =IF(OR(E18="",F18=""),"",E18*F18) | H18: 📋 DEHN / Erico / Furse / Helita
A19: 9.2.5 | B19: Surge protection device (SPD) Type 1+2 at LV panel main incomer | C19: P-100 (Site) / P-108 (Roof) | D19: Nr | E19: 2 | F19: 4500 | G19: =IF(OR(E19="",F19=""),"",E19*F19) | H19: 📋 DEHN / Erico / Furse / Helita
A20: 9.2.6 | B20: Lightning protection design certification, risk assessment per IEC 62305-2 | C20: P-100 (Site) / P-108 (Roof) | D20: Sum | E20: 1 | F20: 8000 | G20: =IF(OR(E20="",F20=""),"",E20*F20) | H20: 📋 DEHN / Erico / Furse / Helita
A21: 9.2.7 | B21: LP testing & DEWA acceptance certificate | C21: P-100 (Site) / P-108 (Roof) | D21: Sum | E21: 1 | F21: 6500 | G21: =IF(OR(E21="",F21=""),"",E21*F21) | H21: 📋 DEHN / Erico / Furse / Helita
A22: Sub-Total 9.2 | G22: =SUM(G15:G21)
A25: BILL 9 — TOTAL CARRIED TO SUMMARY | G25: =SUMIF(A4:A23,"*.*.*",G4:G23)

Sheet Bill 10 - Emergency Lighting
A1: BILL No. 10 — EMERGENCY LIGHTING & LIFE SAFETY
A2: Project: Proposed B+G+8+R Commercial & Residential Building, Plot 6731315, Al Barsha South Third, Dubai, UAE | Job: FA_P379 / CRs B/010/25 | Authority: DEWA (Dubai Electricity & Water Authority)
A3: Item | B3: Description | C3: Reference | D3: Unit | E3: Qty | F3: Rate (AED) | G3: Amount (AED) | H3: Origin / Brand
A4: 10.1 — EMERGENCY LUMINAIRES (3-hour autonomy)
A5: 10.1.1 | B5: Self-contained emergency LED downlight, 3 W, 3-hour duration, IP20, with self-test (corridors, lobbies) | C5: P-103 … P-108 (Floor plans) / P-201 | D5: Nr | E5: 96 | F5: 85 | G5: =IF(OR(E5="",F5=""),"",E5*F5) | H5: 📋 Philips / Osram / Trilux / Thorn / Cooper
A6: 10.1.2 | B6: Self-contained emergency bulkhead, 8 W, 3-hour, IP65 (staircase, plant rooms) | C6: P-103 … P-108 (Floor plans) / P-201 | D6: Nr | E6: 48 | F6: 380 | G6: =IF(OR(E6="",F6=""),"",E6*F6) | H6: 📋 Chloride / Cooper / Tridonic / Hochiki
A7: 10.1.3 | B7: Maintained emergency exit sign LED, single-sided, with arrow pictogram (BS EN 1838) | C7: P-103 … P-108 (Floor plans) / P-201 | D7: Nr | E7: 64 | F7: 320 | G7: =IF(OR(E7="",F7=""),"",E7*F7) | H7: 📋 Chloride / Cooper / Tridonic / Hochiki
A8: 10.1.4 | B8: Maintained emergency exit sign LED, double-sided, ceiling-mounted | C8: P-103 … P-108 (Floor plans) / P-201 | D8: Nr | E8: 18 | F8: 480 | G8: =IF(OR(E8="",F8=""),"",E8*F8) | H8: 📋 Chloride / Cooper / Tridonic / Hochiki
A9: Sub-Total 10.1 | G9: =SUM(G5:G8)
A11: 10.2 — EMERGENCY POWER FOR LIFE-SAFETY EQUIPMENT (FR feeders)
A12: 10.2.1 | B12: Power supply for fire pump panel — Fire-Rated cable from ESMDB-RF, including isolator & terminations | C12: P-200 (Essential) / P-201 (FR feeders) | D12: Set | E12: 1 | F12: 13800 | G12: =IF(OR(E12="",F12=""),"",E12*F12) | H12: 📋 MK / Schneider / Legrand / Hager
A13: 10.2.2 | B13: Power supply for stair pressurisation fans — FR feeder & isolator | C13: P-200 (Essential) / P-201 (FR feeders) | D13: Set | E13: 1 | F13: 110 | G13: =IF(OR(E13="",F13=""),"",E13*F13) | H13: 📋 MK / Schneider / Legrand / Hager
A14: 10.2.3 | B14: Power supply for smoke-extract fans (basement & corridors) — FR feeder & isolator | C14: P-200 (Essential) / P-201 (FR feeders) | D14: Set | E14: 1 | F14: 110 | G14: =IF(OR(E14="",F14=""),"",E14*F14) | H14: 📋 MK / Schneider / Legrand / Hager
A15: 10.2.4 | B15: Power supply for sprinkler-system jockey pump & main pump motor starter | C15: P-200 (Essential) / P-201 (FR feeders) | D15: Set | E15: 1 | F15: 22000 | G15: =IF(OR(E15="",F15=""),"",E15*F15) | H15: 📋
A16: 10.2.5 | B16: Power supply for fire-fighter's lift (2-hour FR feeder) | C16: P-200 (Essential) / P-201 (FR feeders) | D16: Set | E16: 1 | F16: 28000 | G16: =IF(OR(E16="",F16=""),"",E16*F16) | H16: 📋
A17: Sub-Total 10.2 | G17: =SUM(G12:G16)
A19: 10.3 — CENTRAL BATTERY SYSTEM (CBS) — alternative to self-contained
A20: 10.3.1 | B20: CBS cabinet — 24/48 V DC, 3-hour autonomy, sized for total emergency luminaire load (~8 kW for this project), VRLA sealed batteries, charger, supervision, BMS interface, IP31, lockable. Provisional sum. | C20: P-201 (Emergency loop) / P-300 (CBS cabinet) | D20: Sum | E20: 1 | F20: 85000 | G20: =IF(OR(E20="",F20=""),"",E20*F20) | H20: 📋 Chloride / Cooper / Olympia / Hochiki
A21: 10.3.2 | B21: Maintained-feed sub-circuits from CBS to corridor / public-area luminaires — Fire-Rated cable in dedicated FR containment, ID-labelled in red (allow per riser). | C21: P-201 (Emergency loop) / P-300 (CBS cabinet) | D21: m | E21: 180 | F21: 38 | G21: =IF(OR(E21="",F21=""),"",E21*F21) | H21: 📋 Chloride / Cooper / Olympia / Hochiki
A22: 10.3.3 | B22: CBS testing & 3-hour discharge witness test — under controlled outage, recording lumen output and battery voltage decay. | C22: P-201 (Emergency loop) / P-300 (CBS cabinet) | D22: Sum | E22: 1 | F22: 8500 | G22: =IF(OR(E22="",F22=""),"",E22*F22) | H22: 📋
A23: Sub-Total 10.3 | G23: =SUM(G20:G22)
A25: 10.4 — FIRE ALARM / MEP INTEGRATION (DCD requirement)
A26: 10.4.1 | B26: Shunt-trip relay for FAHU isolation on Fire Alarm activation — 24 V DC monitored coil, status feedback to FACP, MCCB shunt-trip module. | C26: Coordinate with FA contractor (FA-001 series) | D26: Nr | E26: 1 | F26: 1800 | G26: =IF(OR(E26="",F26=""),"",E26*F26) | H26: 📋 Schneider / ABB / Siemens / Eaton
A27: 10.4.2 | B27: Shunt-trip relay for AHU isolation per air-handling zone — 24 V DC monitored, status feedback to FACP. (Allow per AHU zone — typical per floor) | C27: Coordinate with FA contractor (FA-001 series) | D27: Nr | E27: 8 | F27: 1800 | G27: =IF(OR(E27="",F27=""),"",E27*F27) | H27: 📋 Schneider / ABB / Siemens / Eaton
A28: 10.4.3 | B28: Lift fire-recall interface module — homes lifts to designated fire-recall floor on Fire Alarm signal, monitored by FACP. (Per lift bank) | C28: Coordinate with FA contractor (FA-001 series) | D28: Nr | E28: 4 | F28: 6500 | G28: =IF(OR(E28="",F28=""),"",E28*F28) | H28: 📋 KONE / Otis / Schindler / Mitsubishi (lift OEM)
A29: 10.4.4 | B29: Smoke / fire damper actuator power supply — 24 V DC monitored, with status feedback (allow per damper, including fire dampers and smoke control). | C29: Coordinate with FA contractor (FA-001 series) | D29: Nr | E29: 24 | F29: 1200 | G29: =IF(OR(E29="",F29=""),"",E29*F29) | H29: 📋 Notifier / Honeywell / Edwards / Hochiki
A30: 10.4.5 | B30: Mag-lock door release on fire alarm — fail-safe release, 24 V DC, monitored relay for FACP signalling. (Per access-controlled fire-route door.) | C30: Coordinate with FA contractor (FA-001 series) | D30: Nr | E30: 12 | F30: 950 | G30: =IF(OR(E30="",F30=""),"",E30*F30) | H30: 📋 Notifier / Honeywell / Edwards / Hochiki
A31: 10.4.6 | B31: FA-BMS interface relay rack — wall-mounted enclosure with 24 V DC PSU, monitored output relays for HVAC / lighting / lift signalling to FACP & BMS. | C31: Coordinate with FA contractor (FA-001 series) | D31: Set | E31: 1 | F31: 18000 | G31: =IF(OR(E31="",F31=""),"",E31*F31) | H31: 📋 Notifier / Honeywell / Edwards / Hochiki
A32: 10.4.7 | B32: FA system tie-in cabling — Fire-Rated 2-core control cable from FACP to interface relays / shunt-trips / damper actuators. (Allow per tie-in.) | C32: Coordinate with FA contractor (FA-001 series) | D32: m | E32: 280 | F32: 65 | G32: =IF(OR(E32="",F32=""),"",E32*F32) | H32: 📋 Schneider / ABB / Siemens / Eaton
A33: Sub-Total 10.4 | G33: =SUM(G26:G32)
A36: BILL 10 — TOTAL CARRIED TO SUMMARY | G36: =SUMIF(A4:A34,"*.*.*",G4:G34)

Sheet Bill 11 - ELV Containment
A1: BILL No. 11 — ELV CONTAINMENT (TEL/DATA, CCTV, ACS, MATV, FA)
A2: Project: Proposed B+G+8+R Commercial & Residential Building, Plot 6731315, Al Barsha South Third, Dubai, UAE | Job: FA_P379 / CRs B/010/25 | Authority: DEWA (Dubai Electricity & Water Authority)
A3: Item | B3: Description | C3: Reference | D3: Unit | E3: Qty | F3: Rate (AED) | G3: Amount (AED) | H3: Origin / Brand
A4: 11.1 — ELV CONTAINMENT — PROVISIONAL (specialist trades)
A5: 11.1.1 | B5: Telephone / data containment — uPVC conduit Ø 25 mm + draw wires from MDF/IDF to apartment outlets | C5: P-010 / Specialist trade | D5: m | E5: 1200 | F5: 48 | G5: =IF(OR(E5="",F5=""),"",E5*F5) | H5: 📋 Marshall Tufflex / Pemsa / Atkore / DSS
A6: 11.1.2 | B6: CCTV containment — uPVC conduit Ø 25 mm + draw wires + back-boxes to camera locations | C6: P-010 / Specialist trade | D6: m | E6: 600 | F6: 48 | G6: =IF(OR(E6="",F6=""),"",E6*F6) | H6: 📋 Marshall Tufflex / Pemsa / Atkore / DSS
A7: 11.1.3 | B7: Access Control containment — conduit + wiring trough at every controlled door | C7: P-010 / Specialist trade | D7: m | E7: 350 | F7: 14 | G7: =IF(OR(E7="",F7=""),"",E7*F7) | H7: 📋 Marshall Tufflex / Pemsa / Atkore / DSS
A8: 11.1.4 | B8: MATV / SMATV containment — conduit + draw wires, MDF to apartment TV points | C8: P-010 / Specialist trade | D8: m | E8: 800 | F8: 14 | G8: =IF(OR(E8="",F8=""),"",E8*F8) | H8: 📋 Marshall Tufflex / Pemsa / Atkore / DSS
A9: 11.1.5 | B9: Fire Alarm containment — fire-rated conduit Ø 25/32 mm at all loops, isolator points (specialist supply by FA contractor) | C9: P-010 / Specialist trade | D9: m | E9: 900 | F9: 99 | G9: =IF(OR(E9="",F9=""),"",E9*F9) | H9: 📋 Marshall Tufflex / Pemsa / Atkore / DSS
A10: 11.1.6 | B10: BMS field cabling containment — conduit + tray at every field-device location (specialist supply by BMS contractor) | C10: P-010 / Specialist trade | D10: m | E10: 600 | F10: 14 | G10: =IF(OR(E10="",F10=""),"",E10*F10) | H10: 📋 Marshall Tufflex / Pemsa / Atkore / DSS
A11: 11.1.7 | B11: Audio-Video / Door-entry containment — conduit + back-boxes | C11: P-010 / Specialist trade | D11: m | E11: 250 | F11: 14 | G11: =IF(OR(E11="",F11=""),"",E11*F11) | H11: 📋 Marshall Tufflex / Pemsa / Atkore / DSS
A12: 11.1.8 | B12: ELV main risers — 100×100 mm GI trunking with separators between systems | C12: P-010 / Specialist trade | D12: m | E12: 80 | F12: 160 | G12: =IF(OR(E12="",F12=""),"",E12*F12) | H12: 📋 Marshall Tufflex / Pemsa / Atkore / DSS
A13: Sub-Total 11.1 | G13: =SUM(G5:G12)
A16: BILL 11 — TOTAL CARRIED TO SUMMARY | G16: =SUMIF(A4:A14,"*.*.*",G4:G14)

Sheet Bill 12 - Metering
A1: BILL No. 12 — METERING & MONITORING
A2: Project: Proposed B+G+8+R Commercial & Residential Building, Plot 6731315, Al Barsha South Third, Dubai, UAE | Job: FA_P379 / CRs B/010/25 | Authority: DEWA (Dubai Electricity & Water Authority)
A3: Item | B3: Description | C3: Reference | D3: Unit | E3: Qty | F3: Rate (AED) | G3: Amount (AED) | H3: Origin / Brand
A4: 12.1 — DEWA SMART METERING — Tenant & Landlord (AMI-ready, DEWA Smart Grid Programme)
A5: 12.1.1 | B5: DEWA-approved smart kWh meter, single-phase, AMI-ready (PLC + RF mesh communication), bi-directional metering capability, Class 1 accuracy, sealed, IEC 62052-11 / IEC 62053-21 compliant — for apartment tenants. Includes anti-tamper detection, configurable load-profile recording, remote-read capability. | C5: P-300 (LV room) / DEWA Smart Grid spec | D5: Nr | E5: 120 | F5: 850 | G5: =IF(OR(E5="",F5=""),"",E5*F5) | H5: 📋 Itron / Landis+Gyr / Iskra (DEWA-listed)
A6: 12.1.2 | B6: DEWA-approved smart kWh meter, three-phase, CT-operated, AMI-ready, bi-directional with consumption + export channel for Shams Dubai net metering (where PV applicable), Class 0.5S accuracy, sealed, IEC 62053-22 — for retail / common services / landlord. | C6: P-300 (LV room) / DEWA Smart Grid spec | D6: Nr | E6: 12 | F6: 2400 | G6: =IF(OR(E6="",F6=""),"",E6*F6) | H6: 📋 Itron / Landis+Gyr / Iskra (DEWA-listed)
A7: 12.1.3 | B7: DEWA-approved smart meter cabinet — DEWA Service Connection Specifications compliant, modular, lockable, ventilated, IP31, with sealed access door for DEWA-only opening, RJ-45 / RS-485 communication ports. | C7: P-300 (LV room) / DEWA Smart Grid spec | D7: Nr | E7: 8 | F7: 3200 | G7: =IF(OR(E7="",F7=""),"",E7*F7) | H7: 📋 Itron / Landis+Gyr / Iskra (DEWA-listed)
A8: 12.1.4 | B8: Current transformers (CTs) for smart-meter feeders — Class 0.5S, 250/5 / 400/5 / 630/5 / 2000/5 ratios per panel schedule, sealed, with DEWA-approved label. | C8: P-300 (LV room) / DEWA Smart Grid spec | D8: Set | E8: 1 | F8: 12000 | G8: =IF(OR(E8="",F8=""),"",E8*F8) | H8: 📋 Schneider PowerLogic / Janitza / Carlo Gavazzi
A9: 12.1.5 | B9: AMI head-end / data-concentrator (PLC + RF mesh gateway) — coordination with DEWA where centralised concentrator is supplied by DEWA; provisional allowance for concentrator location, power supply, and back-haul cabling. | C9: P-300 (LV room) / DEWA Smart Grid spec | D9: Sum | E9: 1 | F9: 28000 | G9: =IF(OR(E9="",F9=""),"",E9*F9) | H9: 📋 Itron / Landis+Gyr / Iskra (DEWA-listed)
A10: Sub-Total 12.1 | G10: =SUM(G5:G9)
A12: 12.2 — PANEL METERING, BMS INTEGRATION & MDM COORDINATION
A13: 12.2.1 | B13: Multi-function digital meter (MFM) on LV panel main incomer & outgoing feeders — V/I/P/Q/PF/THD measurement, MODBUS RTU/TCP communication, Class 0.5 accuracy. | C13: P-300 (LV room) / DEWA Smart Grid spec | D13: Nr | E13: 12 | F13: 2800 | G13: =IF(OR(E13="",F13=""),"",E13*F13) | H13: 📋 Schneider PowerLogic / Janitza / Carlo Gavazzi
A14: 12.2.2 | B14: Energy-monitoring software / SCADA package for panel-level metering — head-end software, dashboards, historical data logging — provisional sum. | C14: P-300 (LV room) / DEWA Smart Grid spec | D14: Sum | E14: 1 | F14: 85000 | G14: =IF(OR(E14="",F14=""),"",E14*F14) | H14: 📋 Itron / Landis+Gyr / Iskra (DEWA-listed)
A15: 12.2.3 | B15: DEWA MDM (Meter Data Management) integration — testing of meter-to-MDM connectivity, data validation, and acceptance per DEWA AMI specifications. Provisional sum. | C15: P-300 (LV room) / DEWA Smart Grid spec | D15: Sum | E15: 1 | F15: 25000 | G15: =IF(OR(E15="",F15=""),"",E15*F15) | H15: 📋 Itron / Landis+Gyr / Iskra (DEWA-listed)
A16: 12.2.4 | B16: Wiring, terminations, CT secondaries, communication cabling (RS-485 / Cat6) for panel-level + smart-meter system. | C16: P-300 (LV room) / DEWA Smart Grid spec | D16: Sum | E16: 1 | F16: 18000 | G16: =IF(OR(E16="",F16=""),"",E16*F16) | H16: 📋 Itron / Landis+Gyr / Iskra (DEWA-listed)
A17: 12.2.5 | B17: DEWA-witnessed meter sealing & acceptance — including AMI commissioning and remote-read verification. | C17: P-300 (LV room) / DEWA Smart Grid spec | D17: Sum | E17: 1 | F17: 12000 | G17: =IF(OR(E17="",F17=""),"",E17*F17) | H17: 📋 Itron / Landis+Gyr / Iskra (DEWA-listed)
A18: Sub-Total 12.2 | G18: =SUM(G13:G17)
A21: BILL 12 — TOTAL CARRIED TO SUMMARY | G21: =SUMIF(A4:A19,"*.*.*",G4:G19)

Sheet Bill 13 - Test & Commissioning
A1: BILL No. 13 — TESTING, COMMISSIONING & DEWA APPROVAL
A2: Project: Proposed B+G+8+R Commercial & Residential Building, Plot 6731315, Al Barsha South Third, Dubai, UAE | Job: FA_P379 / CRs B/010/25 | Authority: DEWA (Dubai Electricity & Water Authority)
A3: Item | B3: Description | C3: Reference | D3: Unit | E3: Qty | F3: Rate (AED) | G3: Amount (AED) | H3: Origin / Brand
A4: 13.1 — ROUTINE ELECTRICAL TESTS (Pre-energisation)
A5: 13.1.1 | B5: Insulation resistance testing of all LV cables — 500 V/1000 V Megger, full report. | C5: DEWA / DM / DCD / IEC 60364-6 | D5: Sum | E5: 1 | F5: 18000 | G5: =IF(OR(E5="",F5=""),"",E5*F5) | H5: 📋 — (contractor selection)
A6: 13.1.2 | B6: Continuity & polarity testing of all final circuits. | C6: DEWA / DM / DCD / IEC 60364-6 | D6: Sum | E6: 1 | F6: 12000 | G6: =IF(OR(E6="",F6=""),"",E6*F6) | H6: 📋 — (contractor selection)
A7: 13.1.3 | B7: Earth fault loop impedance testing at every distribution board. | C7: DEWA / DM / DCD / IEC 60364-6 | D7: Sum | E7: 1 | F7: 2400 | G7: =IF(OR(E7="",F7=""),"",E7*F7) | H7: 📋 — (contractor selection)
A8: 13.1.4 | B8: Phase rotation & balance testing at all 3-phase feeders. | C8: DEWA / DM / DCD / IEC 60364-6 | D8: Sum | E8: 1 | F8: 6500 | G8: =IF(OR(E8="",F8=""),"",E8*F8) | H8: 📋 — (contractor selection)
A9: 13.1.5 | B9: RCD testing at all RCD/RCBO-protected circuits. | C9: DEWA / DM / DCD / IEC 60364-6 | D9: Sum | E9: 1 | F9: 5500 | G9: =IF(OR(E9="",F9=""),"",E9*F9) | H9: 📋 — (contractor selection)
A10: Sub-Total 13.1 | G10: =SUM(G5:G9)
A12: 13.2 — SYSTEM COMMISSIONING (Energisation & Performance)
A13: 13.2.1 | B13: ATS changeover testing — simulate mains failure, verify auto-switchover, full load test. | C13: DEWA / DM / DCD / IEC 60364-6 | D13: Sum | E13: 1 | F13: 80000 | G13: =IF(OR(E13="",F13=""),"",E13*F13) | H13: 📋 ABB / Socomec / Cummins / GE
A14: 13.2.2 | B14: Standby generator full-load test — including load bank (if required), 4-hour run, fuel consumption recording. | C14: DEWA / DM / DCD / IEC 60364-6 | D14: Sum | E14: 1 | F14: 28000 | G14: =IF(OR(E14="",F14=""),"",E14*F14) | H14: 📋 Cummins / Caterpillar / FG Wilson / Perkins
A15: 13.2.3 | B15: Power-factor correction verification — record PF before/after capacitor bank energisation, harmonic analysis. | C15: DEWA / DM / DCD / IEC 60364-6 | D15: Sum | E15: 1 | F15: 8500 | G15: =IF(OR(E15="",F15=""),"",E15*F15) | H15: 📋 — (contractor selection)
A16: 13.2.4 | B16: Earthing system resistance test (Megger DET) at every electrode and MEB. | C16: DEWA / DM / DCD / IEC 60364-6 | D16: Sum | E16: 1 | F16: 1200 | G16: =IF(OR(E16="",F16=""),"",E16*F16) | H16: 📋 Erico / Furse / DEHN / Pentair
A17: 13.2.5 | B17: Lightning protection continuity test, including down-conductor resistance. | C17: DEWA / DM / DCD / IEC 60364-6 | D17: Sum | E17: 1 | F17: 5500 | G17: =IF(OR(E17="",F17=""),"",E17*F17) | H17: 📋 DEHN / Erico / Furse / Helita
A18: 13.2.6 | B18: Emergency lighting 3-hour duration test under controlled outage. | C18: DEWA / DM / DCD / IEC 60364-6 | D18: Sum | E18: 1 | F18: 4500 | G18: =IF(OR(E18="",F18=""),"",E18*F18) | H18: 📋 — (contractor selection)
A19: Sub-Total 13.2 | G19: =SUM(G13:G18)
A21: 13.3 — AUTHORITY APPROVALS & AS-BUILT DOCUMENTATION
A22: 13.3.1 | B22: DEWA Inspection Coordination — coordinating multiple DEWA inspection visits during construction (cable rough-in, panel termination, earthing, metering pre-energisation, energising, post-energisation), submission of inspection requests, attendance, and rectifications until each stage is signed off. | C22: DEWA / DM / DCD / IEC 60364-6 | D22: Sum | E22: 1 | F22: 35000 | G22: =IF(OR(E22="",F22=""),"",E22*F22) | H22: 📋 DEWA / DM / DCD / RTA
A23: 13.3.2 | B23: DEWA Final Approval & Energisation — application fees, witnessed routine test, meter sealing, energising-permit issue. Provisional sum. | C23: DEWA / DM / DCD / IEC 60364-6 | D23: Sum | E23: 1 | F23: 50000 | G23: =IF(OR(E23="",F23=""),"",E23*F23) | H23: 📋 DEWA / DM / DCD / RTA
A24: 13.3.3 | B24: Dubai Municipality (DM) electrical inspection clearance — coordination with DM inspectors, attendance, and rectifications until clearance is obtained for occupancy / completion certificate. | C24: DEWA / DM / DCD / IEC 60364-6 | D24: Sum | E24: 1 | F24: 18000 | G24: =IF(OR(E24="",F24=""),"",E24*F24) | H24: 📋 DEWA / DM / DCD / RTA
A25: 13.3.4 | B25: DCD (Dubai Civil Defence) electrical clearance for life-safety installations — emergency lighting witnessed test, fire-pump power-supply inspection, smoke-control fan circuit verification. | C25: DEWA / DM / DCD / IEC 60364-6 | D25: Sum | E25: 1 | F25: 22000 | G25: =IF(OR(E25="",F25=""),"",E25*F25) | H25: 📋 DEWA / DM / DCD / RTA
A26: 13.3.5 | B26: As-Built Drawings — Consultant Approval. As-Built drawings (AutoCAD .dwg + PDF, 4 hard-copy bound sets), submitted to consultant for review, revisions until approved and signed. | C26: DEWA / DM / DCD / IEC 60364-6 | D26: Sum | E26: 1 | F26: 28000 | G26: =IF(OR(E26="",F26=""),"",E26*F26) | H26: 📋 DEWA / DM / DCD / RTA
A27: 13.3.6 | B27: As-Built Drawings — DEWA Approval. As-Built submission to DEWA in DEWA-required format (specific layer / title-block / electronic file structure), revisions until approved and filed by DEWA. | C27: DEWA / DM / DCD / IEC 60364-6 | D27: Sum | E27: 1 | F27: 32000 | G27: =IF(OR(E27="",F27=""),"",E27*F27) | H27: 📋 DEWA / DM / DCD / RTA
